Workbook

Sheet README
B2: REAL ESTATE FEASIBILITY ENGINE
B3: What it is | C3: An adaptive feasibility model: describe the project with rules (quarters, curves, payment plans) and the engine builds every quarter itself.
B4: Sheets | C4: DASHBOARD (one-page summary) → STRESS (live what-if tables) → INPUTS (everything you type) → TIMELINE (calendar, Gantt & on/off flags) → CURVES (quarterly % for sales, construction & every cost head) → COLLECTIONS (bookings → CLP cash received) → CASHFLOW (outflows, net cash, IRR, NPV) → OUTPUT (revenue, cost, P&L, JV split, key metrics) → LISTS (dropdown sources & conversions).
B6: HOW TO USE
B7: 1. Type only in inputs | C7: Blue-on-yellow cells. Black cells are formulas – never overwrite them.
B8: 2. Quarters | C8: All timing is a quarter number from the project start (Q1). Type 3 → shows Q3.
B9: 3. Products | C9: One row per product with zone and category. Category decides which construction cost head it lands in. Project type (Villa / Apartments / Plotted / Mixed) automatically switches off products of other zones.
B10: 4. Product timing | C10: Section 5B: each product's launch and construction start can be a fixed quarter, or linked to another product's launch / sales end / construction start / 50% / end.
B11: 5. Cost heads | C11: All 21 standard heads + 3 spare rows. Each has an Applicable switch, its own calculation and a phasing curve.
B12: 6. Payment plans | C12: Milestones tied to booking or construction %, so they move automatically with the schedule.
B13: 7. Scenarios | C13: One dropdown switches Best / Base / Worst case.
B14: 8. Checks | C14: INPUTS must show ✔ ALL CHECKS PASSED before results are used.
B15: 9. Stress tests | C15: STRESS sheet tables re-run the whole model automatically. If Excel is slow: Formulas → Calculation Options → Automatic except for Data Tables, then F9.
B17: COLOUR CODE
B18: Blue on yellow | C18: Input
B19: Black | C19: Formula
B20: Green | C20: Link from another sheet
B22: ROADMAP
B23: Step 1 ✔ | C23: Inputs, cost heads, calculators, output statements
B24: Step 2 ✔ | C24: Timeline engine (TIMELINE sheet: 40 self-switching quarter columns + Gantt)
B25: Step 3 ✔ | C25: Curve engine (CURVES sheet: curve names → quarterly %, always 100%)
B26: Step 4 ✔ | C26: COLLECTIONS sheet: bookings, CLP milestone triggers, catch-up, collections, LO/developer split
B27: Step 5 ✔ | C27: CASHFLOW sheet: outflows, landowner payments, project & developer cash flow, IRR, NPV, peak investment, break-even, FY summary
B28: Step 6 ✔ | C28: DASHBOARD sheet: KPI tiles with benchmark colours, auto-written takeaways, 6 charts incl. Gantt
B29: Step 7 ✔ | C29: STRESS sheet: scenario comparison, price / cost / speed / delay sensitivities, 2-way grids, headroom
B31: Disclaimer | C31: Illustrative sample figures. Tax, stamp duty, BAR and regulatory rates must be verified before real use.

Sheet DASHBOARD
B2: =INPUTS!$C$17&" — FEASIBILITY DASHBOARD" -> Project Aurora (Sample) — FEASIBILITY DASHBOARD
B3: =INPUTS!$C$18&" | "&INPUTS!$C$19&" | "&INPUTS!$C$21&" deal | Scenario: "&INPUTS!$C$23&" | "&TEXT(INPUTS!$C$39,"0.0")&" acres, "&TEXT(INPUTS!$F$98,"#,##0")&" sq ft saleable | "&TEXT(INPUTS!$C$20,"mmm yyyy")&" – "&TEXT(INPUTS!$C$30,"mmm yyyy") -> Sample City, Rajasthan | Mixed Development | JV deal | Scenario: Base Case | 6.2 acres, 920,000 sq ft saleable | Jun 2027 – Mar 2032
B4: =INPUTS!$C$7 -> ✔ ALL CHECKS PASSED
B6: GDV (total revenue) | F6: Total cost | J6: EBITDA | N6: PAT
B7: =OUTPUT!$D$23 -> 803 | F7: =OUTPUT!$D$51 -> 630.60532 | J7: =OUTPUT!$D$58 -> 172.39468 | N7: =OUTPUT!$D$60 -> 127.57206
B8: ="₹ "&TEXT(INPUTS!$T$98*INPUTS!$C$25/MAX(1,INPUTS!$F$98),"#,##0")&" per sq ft" -> ₹ 8,728 per sq ft | F8: =TEXT(OUTPUT!$F$51,"0.0%")&" of GDV" -> 78.5% of GDV | J8: =TEXT(OUTPUT!$F$58,"0.0%")&" margin · benchmark "&TEXT(INPUTS!$C$434,"0%") -> 21.5% margin · benchmark 20% | N8: =TEXT(OUTPUT!$F$60,"0.0%")&" margin · tax "&TEXT(INPUTS!$C$425,"0.0%") -> 15.9% margin · tax 26.0%
B10: Developer IRR (pre-tax) | F10: Project IRR | J10: Developer NPV | N10: Equity multiple
B11: =CASHFLOW!$C$69 -> 1.1017638 | F11: =CASHFLOW!$C$67 -> 4.490612 | J11: =CASHFLOW!$C$72 -> 90.628114 | N11: =OUTPUT!$D$75 -> 1.4732968
B12: ="Benchmark "&TEXT(INPUTS!$C$429,"0%")&" · post-tax ≈ "&IFERROR(TEXT(CASHFLOW!$C$70,"0%"),"n/a") -> Benchmark 18% · post-tax ≈ 84% | F12: ="Benchmark "&TEXT(INPUTS!$C$428,"0%")&" · before landowner share" -> Benchmark 22% · before landowner share | J12: ="@ "&TEXT(INPUTS!$C$426,"0%")&" cost of equity" -> @ 18% cost of equity | N12: ="Benchmark "&TEXT(INPUTS!$C$430,"0.0")&"x · cash multiple "&TEXT(CASHFLOW!$C$83,"0.0")&"x" -> Benchmark 2.0x · cash multiple 4.4x
B14: Peak investment | F14: Payback (developer) | J14: ROCE (annualised) | N14: CAGR
B15: =CASHFLOW!$C$73 -> 34.287321 | F15: =CASHFLOW!$C$81 -> Q8 | J15: =OUTPUT!$D$78 -> 1.2009637 | N15: =OUTPUT!$D$80 -> 0.40338456
B16: ="Reached in "&CASHFLOW!$C$74&IF(CASHFLOW!$C$73>0," ("&TEXT(CASHFLOW!$C$75,"mmm yy")&")","") -> Reached in Q2 (Sep 27) | F16: =IF(CASHFLOW!$C$81="never","Cash never recovered",TEXT(CASHFLOW!$C$82,"mmm yyyy")&" · first +ve quarter "&CASHFLOW!$C$79) -> Mar 2029 · first +ve quarter Q3 | J16: ="Benchmark "&TEXT(INPUTS!$C$431,"0%")&" · on initial investment" -> Benchmark 30% · on initial investment | N16: ="Benchmark "&TEXT(INPUTS!$C$432,"0%")&" · over "&TEXT(INPUTS!$C$32,"0.0")&" yrs" -> Benchmark 30% · over 5.0 yrs
B17: Green = beats the benchmark set in INPUTS Section 9; amber = review.
B18: KEY TAKEAWAYS (auto-written from the model)
B19: ="1. The project generates ₹"&TEXT(OUTPUT!$D$23,"#,##0")&" Cr of revenue against ₹"&TEXT(OUTPUT!$D$51,"#,##0")&" Cr of cost – EBITDA ₹"&TEXT(OUTPUT!$D$58,"#,##0")&" Cr ("&TEXT(OUTPUT!$F$58,"0.0%")&") and PAT ₹"&TEXT(OUTPUT!$D$60,"#,##0")&" Cr ("&TEXT(OUTPUT!$F$60,"0.0%")&")." -> 1. The project generates ₹803 Cr of revenue against ₹631 Cr of cost – EBITDA ₹172 Cr (21.5%) and PAT ₹128 Cr (15.9%).
B20: ="2. The developer earns a pre-tax IRR of "&IFERROR(TEXT(CASHFLOW!$C$69,"0%"),"n/a")&" against an "&TEXT(INPUTS!$C$429,"0%")&" hurdle, with an NPV of ₹"&TEXT(CASHFLOW!$C$72,"#,##0.0")&" Cr at the "&TEXT(INPUTS!$C$426,"0%")&" cost of equity." -> 2. The developer earns a pre-tax IRR of 110% against an 18% hurdle, with an NPV of ₹90.6 Cr at the 18% cost of equity.
B21: ="3. Maximum funding needed is ₹"&TEXT(CASHFLOW!$C$73,"#,##0.0")&" Cr ("&CASHFLOW!$C$74&"); the developer gets all of it back by "&CASHFLOW!$C$81&IF(CASHFLOW!$C$81="never",""," ("&TEXT(CASHFLOW!$C$82,"mmm yyyy")&")")&IF(INPUTS!$C$21="JV"," – construction is largely funded by customer collections."," – most of this peak is the land payment, made before customer collections build up.") -> 3. Maximum funding needed is ₹34.3 Cr (Q2); the developer gets all of it back by Q8 (Mar 2029) – construction is largely funded by customer collections.
B22: =IF(INPUTS!$C$21="JV","4. The landowner receives ₹"&TEXT(INPUTS!$G$128,"#,##0.0")&" Cr ("&TEXT(INPUTS!$C$45,"0%")&" revenue share) – about ₹"&TEXT(INPUTS!$D$65,"#,##0")&" per sq yd, "&TEXT(INPUTS!$D$66,"0%")&" above today's market rate – paid out of collections after his ₹"&TEXT(INPUTS!$C$189*INPUTS!$C$55,"#,##0.0")&" Cr advance is recovered.","4. Outright deal: land of ₹"&TEXT(INPUTS!$G$128,"#,##0.0")&" Cr is paid as per the land payment schedule, which is why peak funding is high.") -> 4. The landowner receives ₹257.0 Cr (32% revenue share) – about ₹85,653 per sq yd, 43% above today's market rate – paid out of collections after his ₹18.0 Cr advance is recovered.
B88: CHART DATA (linked – do not edit)
B89: Cost group | D89: ₹ Cr
B90: Land / landowner share | D90: =INPUTS!$G$128+INPUTS!$G$129+INPUTS!$G$130 -> 259.98075
B91: Construction | D91: =INPUTS!$G$153 -> 270.4
B92: Marketing & sales | D92: =INPUTS!$G$139 -> 56.21
B93: Corporate overheads | D93: =INPUTS!$G$138 -> 32.12
B94: Approvals, legal & BAR | D94: =INPUTS!$G$140+INPUTS!$G$148 -> 10.054574
B95: Other (EWS, contingency, EDC, GST, AIF…) | D95: =INPUTS!$G$152-SUM(D90:D94) -> 1.84
B97: Revenue by type | D97: ₹ Cr
B98: =SUBSTITUTE(INPUTS!$B$119," saleable area","") -> Residential | D98: =INPUTS!$F$119 -> 725
B99: =SUBSTITUTE(INPUTS!$B$120," saleable area","") -> Commercial | D99: =INPUTS!$F$120 -> 42
B100: =SUBSTITUTE(INPUTS!$B$121," saleable area","") -> Studio | D100: =INPUTS!$F$121 -> 36
B101: =SUBSTITUTE(INPUTS!$B$122," saleable area","") -> Institutional | D101: =INPUTS!$F$122 -> 0
B102: =SUBSTITUTE(INPUTS!$B$123," saleable area","") -> EWS / LIG area | D102: =INPUTS!$F$123 -> 0
B104: Timeline (Gantt) – included products only | D104: Offset | E104: Selling | F104: Building | H104: # included up to row
B105: =IF(COUNTIF(INPUTS!$E$88:$E$97,"Yes")>=1,INDEX(INPUTS!$B$88:$B$97,MATCH(1,$H$105:$H$114,0))&" – selling","") -> Villas – selling | D105: =IF(COUNTIF(INPUTS!$E$88:$E$97,"Yes")>=1,INDEX(INPUTS!$P$88:$P$97,MATCH(1,$H$105:$H$114,0))-1,0) -> 2 | E105: =IF(COUNTIF(INPUTS!$E$88:$E$97,"Yes")>=1,INDEX(INPUTS!$Q$88:$Q$97,MATCH(1,$H$105:$H$114,0))-INDEX(INPUTS!$P$88:$P$97,MATCH(1,$H$105:$H$114,0))+1,0) -> 8 | F105: =0 -> 0 | H105: =COUNTIF(INPUTS!$E$88:$E$88,"Yes") -> 1
B106: =IF(COUNTIF(INPUTS!$E$88:$E$97,"Yes")>=1,INDEX(INPUTS!$B$88:$B$97,MATCH(1,$H$105:$H$114,0))&" – building","") -> Villas – building | D106: =IF(COUNTIF(INPUTS!$E$88:$E$97,"Yes")>=1,INDEX(INPUTS!$R$88:$R$97,MATCH(1,$H$105:$H$114,0))-1,0) -> 3 | E106: =0 -> 0 | F106: =IF(COUNTIF(INPUTS!$E$88:$E$97,"Yes")>=1,INDEX(INPUTS!$S$88:$S$97,MATCH(1,$H$105:$H$114,0))-INDEX(INPUTS!$R$88:$R$97,MATCH(1,$H$105:$H$114,0))+1,0) -> 12 | H106: =COUNTIF(INPUTS!$E$88:$E$89,"Yes") -> 2
B107: =IF(COUNTIF(INPUTS!$E$88:$E$97,"Yes")>=2,INDEX(INPUTS!$B$88:$B$97,MATCH(2,$H$105:$H$114,0))&" – selling","") -> Apartments – Towers A & B – selling | D107: =IF(COUNTIF(INPUTS!$E$88:$E$97,"Yes")>=2,INDEX(INPUTS!$P$88:$P$97,MATCH(2,$H$105:$H$114,0))-1,0) -> 3 | E107: =IF(COUNTIF(INPUTS!$E$88:$E$97,"Yes")>=2,INDEX(INPUTS!$Q$88:$Q$97,MATCH(2,$H$105:$H$114,0))-INDEX(INPUTS!$P$88:$P$97,MATCH(2,$H$105:$H$114,0))+1,0) -> 12 | F107: =0 -> 0 | H107: =COUNTIF(INPUTS!$E$88:$E$90,"Yes") -> 3
B108: =IF(COUNTIF(INPUTS!$E$88:$E$97,"Yes")>=2,INDEX(INPUTS!$B$88:$B$97,MATCH(2,$H$105:$H$114,0))&" – building","") -> Apartments – Towers A & B – building | D108: =IF(COUNTIF(INPUTS!$E$88:$E$97,"Yes")>=2,INDEX(INPUTS!$R$88:$R$97,MATCH(2,$H$105:$H$114,0))-1,0) -> 4 | E108: =0 -> 0 | F108: =IF(COUNTIF(INPUTS!$E$88:$E$97,"Yes")>=2,INDEX(INPUTS!$S$88:$S$97,MATCH(2,$H$105:$H$114,0))-INDEX(INPUTS!$R$88:$R$97,MATCH(2,$H$105:$H$114,0))+1,0) -> 16 | H108: =COUNTIF(INPUTS!$E$88:$E$91,"Yes") -> 4
B109: =IF(COUNTIF(INPUTS!$E$88:$E$97,"Yes")>=3,INDEX(INPUTS!$B$88:$B$97,MATCH(3,$H$105:$H$114,0))&" – selling","") -> Studios – selling | D109: =IF(COUNTIF(INPUTS!$E$88:$E$97,"Yes")>=3,INDEX(INPUTS!$P$88:$P$97,MATCH(3,$H$105:$H$114,0))-1,0) -> 5 | E109: =IF(COUNTIF(INPUTS!$E$88:$E$97,"Yes")>=3,INDEX(INPUTS!$Q$88:$Q$97,MATCH(3,$H$105:$H$114,0))-INDEX(INPUTS!$P$88:$P$97,MATCH(3,$H$105:$H$114,0))+1,0) -> 8 | F109: =0 -> 0 | H109: =COUNTIF(INPUTS!$E$88:$E$92,"Yes") -> 4
B110: =IF(COUNTIF(INPUTS!$E$88:$E$97,"Yes")>=3,INDEX(INPUTS!$B$88:$B$97,MATCH(3,$H$105:$H$114,0))&" – building","") -> Studios – building | D110: =IF(COUNTIF(INPUTS!$E$88:$E$97,"Yes")>=3,INDEX(INPUTS!$R$88:$R$97,MATCH(3,$H$105:$H$114,0))-1,0) -> 5 | E110: =0 -> 0 | F110: =IF(COUNTIF(INPUTS!$E$88:$E$97,"Yes")>=3,INDEX(INPUTS!$S$88:$S$97,MATCH(3,$H$105:$H$114,0))-INDEX(INPUTS!$R$88:$R$97,MATCH(3,$H$105:$H$114,0))+1,0) -> 12 | H110: =COUNTIF(INPUTS!$E$88:$E$93,"Yes") -> 4
B111: =IF(COUNTIF(INPUTS!$E$88:$E$97,"Yes")>=4,INDEX(INPUTS!$B$88:$B$97,MATCH(4,$H$105:$H$114,0))&" – selling","") -> High-street retail – selling | D111: =IF(COUNTIF(INPUTS!$E$88:$E$97,"Yes")>=4,INDEX(INPUTS!$P$88:$P$97,MATCH(4,$H$105:$H$114,0))-1,0) -> 7 | E111: =IF(COUNTIF(INPUTS!$E$88:$E$97,"Yes")>=4,INDEX(INPUTS!$Q$88:$Q$97,MATCH(4,$H$105:$H$114,0))-INDEX(INPUTS!$P$88:$P$97,MATCH(4,$H$105:$H$114,0))+1,0) -> 8 | F111: =0 -> 0 | H111: =COUNTIF(INPUTS!$E$88:$E$94,"Yes") -> 4
...

Sheet STRESS
B2: STRESS TESTING — how the deal holds up when things go wrong
B3: Tables below are live Excel Data Tables: each cell re-runs the WHOLE model with the lever value shown. Keep the levers at neutral – the tables flex them automatically.
B4: If Excel feels slow: Formulas → Calculation Options → 'Automatic except for Data Tables', then press F9 to refresh the tables.
B6: A. STRESS LEVERS (inputs – keep at neutral: 0%, 0%, 1.00x, 0, 0)
B7: Lever | C7: Value | D7: Neutral | E7: What it does
B8: Sales price shock | C8: 0 | D8: 0% | E8: Changes every product's sales rate (on top of the scenario)
B9: Construction cost shock | C9: 0 | D9: 0% | E9: Changes every product's construction rate
B10: Sales period multiplier | C10: 1 | D10: 1.00x | E10: 1.5x = every product takes 50% longer to sell
B11: Extra delay (quarters) | C11: 0 | D11: 0 | E11: Pushes every fixed launch & construction start later
B12: Scenario override (0 = use INPUTS) | C12: 0 | D12: 0 | E12: 1 = Best, 2 = Base, 3 = Worst – used by the scenario table
B13: Output selector (technical – keep 1) | C13: 1 | D13: 1 | E13: Lets one table show several outputs; does not change the model
B14: Levers status | C14: =IF(AND($C$8=0,$C$9=0,$C$10=1,$C$11=0,$C$12=0),"Neutral","ACTIVE") -> Neutral
B16: B. SCENARIO COMPARISON – Best / Base / Worst side by side (scenario table in INPUTS Section 3)
B17: Current model → | C17: =OUTPUT!$D$23 -> 803 | D17: =OUTPUT!$D$51 -> 630.60532 | E17: =CASHFLOW!$C$69 -> 1.1017638 | F17: =CASHFLOW!$C$72 -> 90.628114 | G17: =OUTPUT!$D$60 -> 127.57206 | H17: =OUTPUT!$F$60 -> 0.15886932 | I17: =OUTPUT!$D$58 -> 172.39468 | J17: =CASHFLOW!$C$73 -> 34.287321 | K17: =CASHFLOW!$C$81 -> Q8 | L17: =OUTPUT!$D$75 -> 1.4732968
B18: Scenario # | C18: GDV (₹ Cr) | D18: Total cost (₹ Cr) | E18: Developer IRR | F18: Developer NPV (₹ Cr) | G18: PAT (₹ Cr) | H18: PAT margin | I18: EBITDA (₹ Cr) | J18: Peak investment (₹ Cr) | K18: Payback | L18: Equity multiple
B19: =CHOOSE($C$13,OUTPUT!$D$23,OUTPUT!$D$51,CASHFLOW!$C$69,CASHFLOW!$C$72,OUTPUT!$D$60,OUTPUT!$F$60,OUTPUT!$D$58,CASHFLOW!$C$73,CASHFLOW!$C$81,OUTPUT!$D$75) -> 803 | C19: 1 | D19: 2 | E19: 3 | F19: 4 | G19: 5 | H19: 6 | I19: 7 | J19: 8 | K19: 9 | L19: 10
B20: 1 | C20: 843.15 | D20: 647.86982 | E20: 1.5076016 | F20: 111.45569 | G20: 144.50733 | H20: 0.17138983 | I20: 195.28018 | J20: 34.447921 | K20: Q7 | L20: 1.5287446
B21: 2 | C21: 803 | D21: 630.60532 | E21: 1.1017638 | F21: 90.628114 | G21: 127.57206 | H21: 0.15886932 | I21: 172.39468 | J21: 34.287321 | K21: Q8 | L21: 1.4732968
B22: 3 | C22: 742.775 | D22: 624.98857 | E22: 0.40241041 | F22: 35.767409 | G22: 87.161958 | H22: 0.11734638 | I22: 117.78643 | J22: 36.360196 | K22: Q18 | L22: 1.3143729
B24: C1. PRICE SENSITIVITY – sales price shock
B25: Current model → | C25: =CASHFLOW!$C$69 -> 1.1017638 | D25: =CASHFLOW!$C$72 -> 90.628114 | E25: =OUTPUT!$D$60 -> 127.57206 | F25: =OUTPUT!$F$60 -> 0.15886932 | G25: =OUTPUT!$D$58 -> 172.39468 | H25: =CASHFLOW!$C$73 -> 34.287321 | I25: =CASHFLOW!$C$81 -> Q8
B26: Lever value | C26: Developer IRR | D26: Developer NPV (₹ Cr) | E26: PAT (₹ Cr) | F26: PAT margin | G26: EBITDA (₹ Cr) | H26: Peak investment (₹ Cr) | I26: Payback
B27: =CHOOSE($C$13,CASHFLOW!$C$69,CASHFLOW!$C$72,OUTPUT!$D$60,OUTPUT!$F$60,OUTPUT!$D$58,CASHFLOW!$C$73,CASHFLOW!$C$81) -> 1.1017638 | C27: 1 | D27: 2 | E27: 3 | F27: 4 | G27: 5 | H27: 6 | I27: 7
B28: -0.15 | C28: 0.73101435 | D28: 49.224078 | E28: 76.766253 | F28: 0.11246979 | G28: 103.73818 | H28: 33.805521 | I28: Q10
B29: -0.1 | C29: 0.86152253 | D29: 63.025423 | E29: 93.701523 | F29: 0.1296548 | G29: 126.62368 | H29: 33.966121 | I29: Q8
B30: -0.05 | C30: 0.98472309 | D30: 76.826768 | E30: 110.63679 | F30: 0.14503086 | G30: 149.50918 | H30: 34.126721 | I30: Q8
B31: 0 | C31: 1.1017638 | D31: 90.628114 | E31: 127.57206 | F31: 0.15886932 | G31: 172.39468 | H31: 34.287321 | I31: Q8
B32: 0.05 | C32: 1.2135404 | D32: 104.42946 | E32: 144.50733 | F32: 0.17138983 | G32: 195.28018 | H32: 34.447921 | I32: Q8
B33: 0.1 | C33: 1.3207605 | D33: 118.2308 | E33: 161.4426 | F33: 0.18277211 | G33: 218.16568 | H33: 34.608521 | I33: Q8
B34: 0.15 | C34: 1.4223881 | D34: 132.01644 | E34: 178.37787 | F34: 0.19316462 | G34: 241.05118 | H34: 34.769121 | I34: Q8
B36: C2. CONSTRUCTION COST SENSITIVITY – cost overrun
B37: Current model → | C37: =CASHFLOW!$C$69 -> 1.1017638 | D37: =CASHFLOW!$C$72 -> 90.628114 | E37: =OUTPUT!$D$60 -> 127.57206 | F37: =OUTPUT!$F$60 -> 0.15886932 | G37: =OUTPUT!$D$58 -> 172.39468 | H37: =CASHFLOW!$C$73 -> 34.287321 | I37: =CASHFLOW!$C$81 -> Q8
B38: Lever value | C38: Developer IRR | D38: Developer NPV (₹ Cr) | E38: PAT (₹ Cr) | F38: PAT margin | G38: EBITDA (₹ Cr) | H38: Peak investment (₹ Cr) | I38: Payback
B39: =CHOOSE($C$13,CASHFLOW!$C$69,CASHFLOW!$C$72,OUTPUT!$D$60,OUTPUT!$F$60,OUTPUT!$D$58,CASHFLOW!$C$73,CASHFLOW!$C$81) -> 1.1017638 | C39: 1 | D39: 2 | E39: 3 | F39: 4 | G39: 5 | H39: 6 | I39: 7
B40: -0.05 | C40: 1.1781589 | D40: 99.077332 | E40: 137.57686 | F40: 0.1713286 | G40: 185.91468 | H40: 34.287321 | I40: Q8
B41: 0 | C41: 1.1017638 | D41: 90.628114 | E41: 127.57206 | F41: 0.15886932 | G41: 172.39468 | H41: 34.287321 | I41: Q8
B42: 0.05 | C42: 1.0237829 | D42: 82.178895 | E42: 117.56726 | F42: 0.14641004 | G42: 158.87468 | H42: 34.287321 | I42: Q8
B43: 0.1 | C43: 0.94413312 | D43: 73.729677 | E43: 107.56246 | F43: 0.13395076 | G43: 145.35468 | H43: 34.287321 | I43: Q8
B44: 0.15 | C44: 0.86273903 | D44: 65.280459 | E44: 97.557663 | F44: 0.12149149 | G44: 131.83468 | H44: 34.287321 | I44: Q8
B45: 0.2 | C45: 0.77954188 | D45: 56.83124 | E45: 87.552863 | F45: 0.10903221 | G45: 118.31468 | H45: 34.287321 | I45: Q10
...

Sheet INPUTS
B2: REAL ESTATE FEASIBILITY ENGINE — INPUT SHEET
B3: Amounts in ₹ Crore | Areas in sq ft unless stated | Q1 = project start quarter; all timing inputs are quarter numbers (type 3 → shows Q3)
B4: Legend: | C4: Blue on yellow = input | D4: Black = formula | E4: OK / ERROR
B6: 0. MODEL HEALTH
B7: Model status | C7: =IF(C8=0,IF(STRESS!$C$14="Neutral","✔ ALL CHECKS PASSED","⚠ CHECKS PASSED – but STRESS levers are active, results are stressed"),"✖ "&C8&" ERROR(S) – see Section 10") -> ✔ ALL CHECKS PASSED
B8: Number of errors | C8: =COUNTIF($C$438:$C$460,"ERROR") -> 0
B9: GDV (₹ Cr) | C9: =$T$98 -> 803
B10: Total cost (₹ Cr) | C10: =$G$152 -> 630.60532
B11: EBITDA margin | C11: =IF(C9>0,(C9-C10)/C9,0) -> 0.21468827
B12: PAT (₹ Cr) | C12: =(C9-C10)-MAX(0,C9-C10)*$C$425 -> 127.57206
B13: Full statements and key metrics are on the OUTPUT sheet.
B15: 1. PROJECT & TIMELINE
B16: Parameter | C16: Value | D16: Unit | E16: Notes
B17: Project name | C17: Project Aurora (Sample) | D17: Text | E17: Dummy project – illustrative figures only
B18: Location | C18: Sample City, Rajasthan | D18: Text
B19: Project type | C19: Mixed Development | D19: List | E19: Villa / Plotted / Apartments / Mixed Development
B20: Project start (quarter-end date) = Q1 | C20: 46568 | D20: Date | E20: 31-Mar, 30-Jun, 30-Sep or 31-Dec
B21: Deal type | C21: JV | D21: List | E21: JV = landowner revenue share | Outright = land bought for cash
B22: Taxable entity | C22: Company | D22: List | E22: Drives the tax rate (Section 9)
B23: Active scenario | C23: Base Case | D23: List | E23: Section 3
B24: Model horizon (quarters) | C24: 40 | D24: Quarters | E24: Engine length (40 = 10 years). Change only if the engine is extended
B25: Crore divisor | C25: 10000000 | D25: ₹ | E25: 1 Crore = 1,00,00,000 – unit constant
B26: Project lifecycle for ROCE / CAGR – override (optional) | D26: Years | E26: Leave blank to use the derived span below
B27: Derived
B28: Horizon end date | C28: =EOMONTH($C$20,3*($C$24-1)) -> 50130 | D28: Date
B29: Project last active quarter | C29: =MAX($Q$88:$Q$97,$S$88:$S$97) -> 20 | D29: Quarter | E29: Latest product sales-end / construction-end
B30: Project last active date | C30: =IF($C$29>0,EOMONTH($C$20,3*($C$29-1)),"") -> 48304 | D30: Date
B31: Project span (years) | C31: =$C$29/4 -> 5 | D31: Years
B32: Project lifecycle used for ROCE / CAGR | C32: =IF(ISNUMBER($C$26),$C$26,$C$31) -> 5 | D32: Years
B34: 2. LAND
B35: Parameter | C35: Value | D35: Unit | E35: Notes
B36: Land area | C36: 30000 | D36: Sq yd | E36: As per title / sale deed
B37: Land area | C37: =$C$36*LISTS!$C$20 -> 270000 | D37: Sq ft | E37: Conversion factors in LISTS
B38: Land area | C38: =$C$36*LISTS!$C$21 -> 25083.821 | D38: Sq m
B39: Land area | C39: =$C$36*LISTS!$C$22 -> 6.1983471 | D39: Acres
B40: Land area | C40: =$C$36*LISTS!$C$23 -> 9.9173554 | D40: Bigha
B41: Current market rate | C41: 60000 | D41: ₹/sq yd | E41: Put sq yd rate only
B42: DLC rate | C42: 13000 | D42: ₹/sq m | E42: Government guideline value (usually notified per sq m)
B43: DLC rate | C43: =$C$42*LISTS!$C$21 -> 10869.656 | D43: ₹/sq yd | E43: Converted from ₹/sq m
B44: If JV
...

Sheet TIMELINE
B2: TIMELINE ENGINE — 40 quarters that switch themselves on and off
B3: Timeline engine status | C3: =IF(COUNTIF(C205:C210,"ERROR")=0,"OK","ERROR") -> OK
B4: No inputs on this sheet. Every cell reads the INPUTS sheet, so changing a date, duration or scenario re-draws everything here.
B6: A. QUARTER CALENDAR
B7: Quarter number | D7: =COLUMN()-COLUMN($C$7) -> 1 | E7: =COLUMN()-COLUMN($C$7) -> 2 | F7: =COLUMN()-COLUMN($C$7) -> 3 | G7: =COLUMN()-COLUMN($C$7) -> 4 | H7: =COLUMN()-COLUMN($C$7) -> 5 | I7: =COLUMN()-COLUMN($C$7) -> 6 | J7: =COLUMN()-COLUMN($C$7) -> 7 | K7: =COLUMN()-COLUMN($C$7) -> 8 | ... AQ7: =COLUMN()-COLUMN($C$7) -> 40
B8: Quarter label | D8: ="Q"&D$7 -> Q1 | E8: ="Q"&E$7 -> Q2 | F8: ="Q"&F$7 -> Q3 | G8: ="Q"&G$7 -> Q4 | H8: ="Q"&H$7 -> Q5 | I8: ="Q"&I$7 -> Q6 | J8: ="Q"&J$7 -> Q7 | K8: ="Q"&K$7 -> Q8 | ... AQ8: ="Q"&AQ$7 -> Q40
B9: Quarter end date | D9: =EOMONTH(INPUTS!$C$20,3*(D$7-1)) -> 46568 | E9: =EOMONTH(INPUTS!$C$20,3*(E$7-1)) -> 46660 | F9: =EOMONTH(INPUTS!$C$20,3*(F$7-1)) -> 46752 | G9: =EOMONTH(INPUTS!$C$20,3*(G$7-1)) -> 46843 | H9: =EOMONTH(INPUTS!$C$20,3*(H$7-1)) -> 46934 | I9: =EOMONTH(INPUTS!$C$20,3*(I$7-1)) -> 47026 | J9: =EOMONTH(INPUTS!$C$20,3*(J$7-1)) -> 47118 | K9: =EOMONTH(INPUTS!$C$20,3*(K$7-1)) -> 47208 | ... AQ9: =EOMONTH(INPUTS!$C$20,3*(AQ$7-1)) -> 50130
B10: Quarter start date | D10: =EOMONTH(D$9,-3)+1 -> 46478 | E10: =EOMONTH(E$9,-3)+1 -> 46569 | F10: =EOMONTH(F$9,-3)+1 -> 46661 | G10: =EOMONTH(G$9,-3)+1 -> 46753 | H10: =EOMONTH(H$9,-3)+1 -> 46844 | I10: =EOMONTH(I$9,-3)+1 -> 46935 | J10: =EOMONTH(J$9,-3)+1 -> 47027 | K10: =EOMONTH(K$9,-3)+1 -> 47119 | ... AQ10: =EOMONTH(AQ$9,-3)+1 -> 50041
B11: Period | D11: =TEXT(D$10,"mmm")&"–"&TEXT(D$9,"mmm yy") -> Apr–Jun 27 | E11: =TEXT(E$10,"mmm")&"–"&TEXT(E$9,"mmm yy") -> Jul–Sep 27 | F11: =TEXT(F$10,"mmm")&"–"&TEXT(F$9,"mmm yy") -> Oct–Dec 27 | G11: =TEXT(G$10,"mmm")&"–"&TEXT(G$9,"mmm yy") -> Jan–Mar 28 | H11: =TEXT(H$10,"mmm")&"–"&TEXT(H$9,"mmm yy") -> Apr–Jun 28 | I11: =TEXT(I$10,"mmm")&"–"&TEXT(I$9,"mmm yy") -> Jul–Sep 28 | J11: =TEXT(J$10,"mmm")&"–"&TEXT(J$9,"mmm yy") -> Oct–Dec 28 | K11: =TEXT(K$10,"mmm")&"–"&TEXT(K$9,"mmm yy") -> Jan–Mar 29 | ... AQ11: =TEXT(AQ$10,"mmm")&"–"&TEXT(AQ$9,"mmm yy") -> Jan–Mar 37
B12: Financial year end (Apr–Mar) | D12: =YEAR(D$9)+IF(MONTH(D$9)>3,1,0) -> 2028 | E12: =YEAR(E$9)+IF(MONTH(E$9)>3,1,0) -> 2028 | F12: =YEAR(F$9)+IF(MONTH(F$9)>3,1,0) -> 2028 | G12: =YEAR(G$9)+IF(MONTH(G$9)>3,1,0) -> 2028 | H12: =YEAR(H$9)+IF(MONTH(H$9)>3,1,0) -> 2029 | I12: =YEAR(I$9)+IF(MONTH(I$9)>3,1,0) -> 2029 | J12: =YEAR(J$9)+IF(MONTH(J$9)>3,1,0) -> 2029 | K12: =YEAR(K$9)+IF(MONTH(K$9)>3,1,0) -> 2029 | ... AQ12: =YEAR(AQ$9)+IF(MONTH(AQ$9)>3,1,0) -> 2037
B13: Financial year | D13: ="FY "&(D$12-1)&"-"&RIGHT(D$12,2) -> FY 2027-28 | E13: ="FY "&(E$12-1)&"-"&RIGHT(E$12,2) -> FY 2027-28 | F13: ="FY "&(F$12-1)&"-"&RIGHT(F$12,2) -> FY 2027-28 | G13: ="FY "&(G$12-1)&"-"&RIGHT(G$12,2) -> FY 2027-28 | H13: ="FY "&(H$12-1)&"-"&RIGHT(H$12,2) -> FY 2028-29 | I13: ="FY "&(I$12-1)&"-"&RIGHT(I$12,2) -> FY 2028-29 | J13: ="FY "&(J$12-1)&"-"&RIGHT(J$12,2) -> FY 2028-29 | K13: ="FY "&(K$12-1)&"-"&RIGHT(K$12,2) -> FY 2028-29 | ... AQ13: ="FY "&(AQ$12-1)&"-"&RIGHT(AQ$12,2) -> FY 2036-37
B14: Quarter of financial year | D14: ="Q"&(INT(MOD(MONTH(D$9)-4,12)/3)+1) -> Q1 | E14: ="Q"&(INT(MOD(MONTH(E$9)-4,12)/3)+1) -> Q2 | F14: ="Q"&(INT(MOD(MONTH(F$9)-4,12)/3)+1) -> Q3 | G14: ="Q"&(INT(MOD(MONTH(G$9)-4,12)/3)+1) -> Q4 | H14: ="Q"&(INT(MOD(MONTH(H$9)-4,12)/3)+1) -> Q1 | I14: ="Q"&(INT(MOD(MONTH(I$9)-4,12)/3)+1) -> Q2 | J14: ="Q"&(INT(MOD(MONTH(J$9)-4,12)/3)+1) -> Q3 | K14: ="Q"&(INT(MOD(MONTH(K$9)-4,12)/3)+1) -> Q4 | ... AQ14: ="Q"&(INT(MOD(MONTH(AQ$9)-4,12)/3)+1) -> Q4
B15: Project year | D15: ="Y"&ROUNDUP(D$7/4,0) -> Y1 | E15: ="Y"&ROUNDUP(E$7/4,0) -> Y1 | F15: ="Y"&ROUNDUP(F$7/4,0) -> Y1 | G15: ="Y"&ROUNDUP(G$7/4,0) -> Y1 | H15: ="Y"&ROUNDUP(H$7/4,0) -> Y2 | I15: ="Y"&ROUNDUP(I$7/4,0) -> Y2 | J15: ="Y"&ROUNDUP(J$7/4,0) -> Y2 | K15: ="Y"&ROUNDUP(K$7/4,0) -> Y2 | ... AQ15: ="Y"&ROUNDUP(AQ$7/4,0) -> Y10
B16: Within model horizon (1 = yes) | C16: =SUM(D16:AQ16) -> 40 | D16: =--(D$7<=INPUTS!$C$24) -> 1 | E16: =--(E$7<=INPUTS!$C$24) -> 1 | F16: =--(F$7<=INPUTS!$C$24) -> 1 | G16: =--(G$7<=INPUTS!$C$24) -> 1 | H16: =--(H$7<=INPUTS!$C$24) -> 1 | I16: =--(I$7<=INPUTS!$C$24) -> 1 | J16: =--(J$7<=INPUTS!$C$24) -> 1 | K16: =--(K$7<=INPUTS!$C$24) -> 1 | ... AQ16: =--(AQ$7<=INPUTS!$C$24) -> 1
B17: Project active (1 = yes) | C17: =SUM(D17:AQ17) -> 20 | D17: =D$16*--(D$7<=INPUTS!$C$29) -> 1 | E17: =E$16*--(E$7<=INPUTS!$C$29) -> 1 | F17: =F$16*--(F$7<=INPUTS!$C$29) -> 1 | G17: =G$16*--(G$7<=INPUTS!$C$29) -> 1 | H17: =H$16*--(H$7<=INPUTS!$C$29) -> 1 | I17: =I$16*--(I$7<=INPUTS!$C$29) -> 1 | J17: =J$16*--(J$7<=INPUTS!$C$29) -> 1 | K17: =K$16*--(K$7<=INPUTS!$C$29) -> 1 | ... AQ17: =AQ$16*--(AQ$7<=INPUTS!$C$29) -> 0
B18: Project phase | D18: =IF(D$17=0,IF(D$16=0,"Beyond horizon","Post-project"),IF(AND(SUMPRODUCT((INPUTS!$E$88:$E$97="Yes")*(INPUTS!$P$88:$P$97<=D$7)*(INPUTS!$Q$88:$Q$97>=D$7))>0,SUMPRODUCT((INPUTS!$E$88:$E$97="Yes")*(INPUTS!$R$88:$R$97<=D$7)*(INPUTS!$S$88:$S$97>=D$7))>0),"Sales + Constr.",IF(SUMPRODUCT((INPUTS!$E$88:$E$97="Yes")*(INPUTS!$P$88:$P$97<=D$7)*(INPUTS!$Q$88:$Q$97>=D$7))>0,"Sales",IF(SUMPRODUCT((INPUTS!$E$88:$E$97="Yes")*(INPUTS!$R$88:$R$97<=D$7)*(INPUTS!$S$88:$S$97>=D$7))>0,"Construction",IF(D$7<MIN(INPUTS!$P$88:$P$97),"Pre-launch","Completion / handover"))))) -> Pre-launch | E18: =IF(E$17=0,IF(E$16=0,"Beyond horizon","Post-project"),IF(AND(SUMPRODUCT((INPUTS!$E$88:$E$97="Yes")*(INPUTS!$P$88:$P$97<=E$7)*(INPUTS!$Q$88:$Q$97>=E$7))>0,SUMPRODUCT((INPUTS!$E$88:$E$97="Yes")*(INPUTS!$R$88:$R$97<=E$7)*(INPUTS!$S$88:$S$97>=E$7))>0),"Sales + Constr.",IF(SUMPRODUCT((INPUTS!$E$88:$E$97="Yes")*(INPUTS!$P$88:$P$97<=E$7)*(INPUTS!$Q$88:$Q$97>=E$7))>0,"Sales",IF(SUMPRODUCT((INPUTS!$E$88:$E$97="Yes")*(INPUTS!$R$88:$R$97<=E$7)*(INPUTS!$S$88:$S$97>=E$7))>0,"Construction",IF(E$7<MIN(INPUTS!$P$88:$P$97),"Pre-launch","Completion / handover"))))) -> Pre-launch | F18: =IF(F$17=0,IF(F$16=0,"Beyond horizon","Post-project"),IF(AND(SUMPRODUCT((INPUTS!$E$88:$E$97="Yes")*(INPUTS!$P$88:$P$97<=F$7)*(INPUTS!$Q$88:$Q$97>=F$7))>0,SUMPRODUCT((INPUTS!$E$88:$E$97="Yes")*(INPUTS!$R$88:$R$97<=F$7)*(INPUTS!$S$88:$S$97>=F$7))>0),"Sales + Constr.",IF(SUMPRODUCT((INPUTS!$E$88:$E$97="Yes")*(INPUTS!$P$88:$P$97<=F$7)*(INPUTS!$Q$88:$Q$97>=F$7))>0,"Sales",IF(SUMPRODUCT((INPUTS!$E$88:$E$97="Yes")*(INPUTS!$R$88:$R$97<=F$7)*(INPUTS!$S$88:$S$97>=F$7))>0,"Construction",IF(F$7<MIN(INPUTS!$P$88:$P$97),"Pre-launch","Completion / handover"))))) -> Sales | G18: =IF(G$17=0,IF(G$16=0,"Beyond horizon","Post-project"),IF(AND(SUMPRODUCT((INPUTS!$E$88:$E$97="Yes")*(INPUTS!$P$88:$P$97<=G$7)*(INPUTS!$Q$88:$Q$97>=G$7))>0,SUMPRODUCT((INPUTS!$E$88:$E$97="Yes")*(INPUTS!$R$88:$R$97<=G$7)*(INPUTS!$S$88:$S$97>=G$7))>0),"Sales + Constr.",IF(SUMPRODUCT((INPUTS!$E$88:$E$97="Yes")*(INPUTS!$P$88:$P$97<=G$7)*(INPUTS!$Q$88:$Q$97>=G$7))>0,"Sales",IF(SUMPRODUCT((INPUTS!$E$88:$E$97="Yes")*(INPUTS!$R$88:$R$97<=G$7)*(INPUTS!$S$88:$S$97>=G$7))>0,"Construction",IF(G$7<MIN(INPUTS!$P$88:$P$97),"Pre-launch","Completion / handover"))))) -> Sales + Constr. | H18: =IF(H$17=0,IF(H$16=0,"Beyond horizon","Post-project"),IF(AND(SUMPRODUCT((INPUTS!$E$88:$E$97="Yes")*(INPUTS!$P$88:$P$97<=H$7)*(INPUTS!$Q$88:$Q$97>=H$7))>0,SUMPRODUCT((INPUTS!$E$88:$E$97="Yes")*(INPUTS!$R$88:$R$97<=H$7)*(INPUTS!$S$88:$S$97>=H$7))>0),"Sales + Constr.",IF(SUMPRODUCT((INPUTS!$E$88:$E$97="Yes")*(INPUTS!$P$88:$P$97<=H$7)*(INPUTS!$Q$88:$Q$97>=H$7))>0,"Sales",IF(SUMPRODUCT((INPUTS!$E$88:$E$97="Yes")*(INPUTS!$R$88:$R$97<=H$7)*(INPUTS!$S$88:$S$97>=H$7))>0,"Construction",IF(H$7<MIN(INPUTS!$P$88:$P$97),"Pre-launch","Completion / handover"))))) -> Sales + Constr. | I18: =IF(I$17=0,IF(I$16=0,"Beyond horizon","Post-project"),IF(AND(SUMPRODUCT((INPUTS!$E$88:$E$97="Yes")*(INPUTS!$P$88:$P$97<=I$7)*(INPUTS!$Q$88:$Q$97>=I$7))>0,SUMPRODUCT((INPUTS!$E$88:$E$97="Yes")*(INPUTS!$R$88:$R$97<=I$7)*(INPUTS!$S$88:$S$97>=I$7))>0),"Sales + Constr.",IF(SUMPRODUCT((INPUTS!$E$88:$E$97="Yes")*(INPUTS!$P$88:$P$97<=I$7)*(INPUTS!$Q$88:$Q$97>=I$7))>0,"Sales",IF(SUMPRODUCT((INPUTS!$E$88:$E$97="Yes")*(INPUTS!$R$88:$R$97<=I$7)*(INPUTS!$S$88:$S$97>=I$7))>0,"Construction",IF(I$7<MIN(INPUTS!$P$88:$P$97),"Pre-launch","Completion / handover"))))) -> Sales + Constr. | J18: =IF(J$17=0,IF(J$16=0,"Beyond horizon","Post-project"),IF(AND(SUMPRODUCT((INPUTS!$E$88:$E$97="Yes")*(INPUTS!$P$88:$P$97<=J$7)*(INPUTS!$Q$88:$Q$97>=J$7))>0,SUMPRODUCT((INPUTS!$E$88:$E$97="Yes")*(INPUTS!$R$88:$R$97<=J$7)*(INPUTS!$S$88:$S$97>=J$7))>0),"Sales + Constr.",IF(SUMPRODUCT((INPUTS!$E$88:$E$97="Yes")*(INPUTS!$P$88:$P$97<=J$7)*(INPUTS!$Q$88:$Q$97>=J$7))>0,"Sales",IF(SUMPRODUCT((INPUTS!$E$88:$E$97="Yes")*(INPUTS!$R$88:$R$97<=J$7)*(INPUTS!$S$88:$S$97>=J$7))>0,"Construction",IF(J$7<MIN(INPUTS!$P$88:$P$97),"Pre-launch","Completion / handover"))))) -> Sales + Constr. | K18: =IF(K$17=0,IF(K$16=0,"Beyond horizon","Post-project"),IF(AND(SUMPRODUCT((INPUTS!$E$88:$E$97="Yes")*(INPUTS!$P$88:$P$97<=K$7)*(INPUTS!$Q$88:$Q$97>=K$7))>0,SUMPRODUCT((INPUTS!$E$88:$E$97="Yes")*(INPUTS!$R$88:$R$97<=K$7)*(INPUTS!$S$88:$S$97>=K$7))>0),"Sales + Constr.",IF(SUMPRODUCT((INPUTS!$E$88:$E$97="Yes")*(INPUTS!$P$88:$P$97<=K$7)*(INPUTS!$Q$88:$Q$97>=K$7))>0,"Sales",IF(SUMPRODUCT((INPUTS!$E$88:$E$97="Yes")*(INPUTS!$R$88:$R$97<=K$7)*(INPUTS!$S$88:$S$97>=K$7))>0,"Construction",IF(K$7<MIN(INPUTS!$P$88:$P$97),"Pre-launch","Completion / handover"))))) -> Sales + Constr. | ... AQ18: =IF(AQ$17=0,IF(AQ$16=0,"Beyond horizon","Post-project"),IF(AND(SUMPRODUCT((INPUTS!$E$88:$E$97="Yes")*(INPUTS!$P$88:$P$97<=AQ$7)*(INPUTS!$Q$88:$Q$97>=AQ$7))>0,SUMPRODUCT((INPUTS!$E$88:$E$97="Yes")*(INPUTS!$R$88:$R$97<=AQ$7)*(INPUTS!$S$88:$S$97>=AQ$7))>0),"Sales + Constr.",IF(SUMPRODUCT((INPUTS!$E$88:$E$97="Yes")*(INPUTS!$P$88:$P$97<=AQ$7)*(INPUTS!$Q$88:$Q$97>=AQ$7))>0,"Sales",IF(SUMPRODUCT((INPUTS!$E$88:$E$97="Yes")*(INPUTS!$R$88:$R$97<=AQ$7)*(INPUTS!$S$88:$S$97>=AQ$7))>0,"Construction",IF(AQ$7<MIN(INPUTS!$P$88:$P$97),"Pre-launch","Completion / handover"))))) -> Post-project
B20: B. GANTT VIEW (S = selling, C = under construction, S+C = both, ✓ = construction complete)
B21: =IF(INPUTS!$E$88="Yes",INPUTS!$B$88,"(product row 1 – off)") -> Villas | D21: =IF(AND(AND(INPUTS!$E$88="Yes",D$16=1,D$7>=INPUTS!$P$88,D$7<=INPUTS!$Q$88),AND(INPUTS!$E$88="Yes",D$16=1,D$7>=INPUTS!$R$88,D$7<=INPUTS!$S$88)),"S+C",IF(AND(INPUTS!$E$88="Yes",D$16=1,D$7>=INPUTS!$P$88,D$7<=INPUTS!$Q$88),"S",IF(AND(INPUTS!$E$88="Yes",D$16=1,D$7>=INPUTS!$R$88,D$7<=INPUTS!$S$88),"C",IF(AND(INPUTS!$E$88="Yes",D$17=1,D$7>INPUTS!$S$88),"✓","")))) | E21: =IF(AND(AND(INPUTS!$E$88="Yes",E$16=1,E$7>=INPUTS!$P$88,E$7<=INPUTS!$Q$88),AND(INPUTS!$E$88="Yes",E$16=1,E$7>=INPUTS!$R$88,E$7<=INPUTS!$S$88)),"S+C",IF(AND(INPUTS!$E$88="Yes",E$16=1,E$7>=INPUTS!$P$88,E$7<=INPUTS!$Q$88),"S",IF(AND(INPUTS!$E$88="Yes",E$16=1,E$7>=INPUTS!$R$88,E$7<=INPUTS!$S$88),"C",IF(AND(INPUTS!$E$88="Yes",E$17=1,E$7>INPUTS!$S$88),"✓","")))) | F21: =IF(AND(AND(INPUTS!$E$88="Yes",F$16=1,F$7>=INPUTS!$P$88,F$7<=INPUTS!$Q$88),AND(INPUTS!$E$88="Yes",F$16=1,F$7>=INPUTS!$R$88,F$7<=INPUTS!$S$88)),"S+C",IF(AND(INPUTS!$E$88="Yes",F$16=1,F$7>=INPUTS!$P$88,F$7<=INPUTS!$Q$88),"S",IF(AND(INPUTS!$E$88="Yes",F$16=1,F$7>=INPUTS!$R$88,F$7<=INPUTS!$S$88),"C",IF(AND(INPUTS!$E$88="Yes",F$17=1,F$7>INPUTS!$S$88),"✓","")))) -> S | G21: =IF(AND(AND(INPUTS!$E$88="Yes",G$16=1,G$7>=INPUTS!$P$88,G$7<=INPUTS!$Q$88),AND(INPUTS!$E$88="Yes",G$16=1,G$7>=INPUTS!$R$88,G$7<=INPUTS!$S$88)),"S+C",IF(AND(INPUTS!$E$88="Yes",G$16=1,G$7>=INPUTS!$P$88,G$7<=INPUTS!$Q$88),"S",IF(AND(INPUTS!$E$88="Yes",G$16=1,G$7>=INPUTS!$R$88,G$7<=INPUTS!$S$88),"C",IF(AND(INPUTS!$E$88="Yes",G$17=1,G$7>INPUTS!$S$88),"✓","")))) -> S+C | H21: =IF(AND(AND(INPUTS!$E$88="Yes",H$16=1,H$7>=INPUTS!$P$88,H$7<=INPUTS!$Q$88),AND(INPUTS!$E$88="Yes",H$16=1,H$7>=INPUTS!$R$88,H$7<=INPUTS!$S$88)),"S+C",IF(AND(INPUTS!$E$88="Yes",H$16=1,H$7>=INPUTS!$P$88,H$7<=INPUTS!$Q$88),"S",IF(AND(INPUTS!$E$88="Yes",H$16=1,H$7>=INPUTS!$R$88,H$7<=INPUTS!$S$88),"C",IF(AND(INPUTS!$E$88="Yes",H$17=1,H$7>INPUTS!$S$88),"✓","")))) -> S+C | I21: =IF(AND(AND(INPUTS!$E$88="Yes",I$16=1,I$7>=INPUTS!$P$88,I$7<=INPUTS!$Q$88),AND(INPUTS!$E$88="Yes",I$16=1,I$7>=INPUTS!$R$88,I$7<=INPUTS!$S$88)),"S+C",IF(AND(INPUTS!$E$88="Yes",I$16=1,I$7>=INPUTS!$P$88,I$7<=INPUTS!$Q$88),"S",IF(AND(INPUTS!$E$88="Yes",I$16=1,I$7>=INPUTS!$R$88,I$7<=INPUTS!$S$88),"C",IF(AND(INPUTS!$E$88="Yes",I$17=1,I$7>INPUTS!$S$88),"✓","")))) -> S+C | J21: =IF(AND(AND(INPUTS!$E$88="Yes",J$16=1,J$7>=INPUTS!$P$88,J$7<=INPUTS!$Q$88),AND(INPUTS!$E$88="Yes",J$16=1,J$7>=INPUTS!$R$88,J$7<=INPUTS!$S$88)),"S+C",IF(AND(INPUTS!$E$88="Yes",J$16=1,J$7>=INPUTS!$P$88,J$7<=INPUTS!$Q$88),"S",IF(AND(INPUTS!$E$88="Yes",J$16=1,J$7>=INPUTS!$R$88,J$7<=INPUTS!$S$88),"C",IF(AND(INPUTS!$E$88="Yes",J$17=1,J$7>INPUTS!$S$88),"✓","")))) -> S+C | K21: =IF(AND(AND(INPUTS!$E$88="Yes",K$16=1,K$7>=INPUTS!$P$88,K$7<=INPUTS!$Q$88),AND(INPUTS!$E$88="Yes",K$16=1,K$7>=INPUTS!$R$88,K$7<=INPUTS!$S$88)),"S+C",IF(AND(INPUTS!$E$88="Yes",K$16=1,K$7>=INPUTS!$P$88,K$7<=INPUTS!$Q$88),"S",IF(AND(INPUTS!$E$88="Yes",K$16=1,K$7>=INPUTS!$R$88,K$7<=INPUTS!$S$88),"C",IF(AND(INPUTS!$E$88="Yes",K$17=1,K$7>INPUTS!$S$88),"✓","")))) -> S+C | ... AQ21: =IF(AND(AND(INPUTS!$E$88="Yes",AQ$16=1,AQ$7>=INPUTS!$P$88,AQ$7<=INPUTS!$Q$88),AND(INPUTS!$E$88="Yes",AQ$16=1,AQ$7>=INPUTS!$R$88,AQ$7<=INPUTS!$S$88)),"S+C",IF(AND(INPUTS!$E$88="Yes",AQ$16=1,AQ$7>=INPUTS!$P$88,AQ$7<=INPUTS!$Q$88),"S",IF(AND(INPUTS!$E$88="Yes",AQ$16=1,AQ$7>=INPUTS!$R$88,AQ$7<=INPUTS!$S$88),"C",IF(AND(INPUTS!$E$88="Yes",AQ$17=1,AQ$7>INPUTS!$S$88),"✓",""))))
B22: =IF(INPUTS!$E$89="Yes",INPUTS!$B$89,"(product row 2 – off)") -> Apartments – Towers A & B | D22: =IF(AND(AND(INPUTS!$E$89="Yes",D$16=1,D$7>=INPUTS!$P$89,D$7<=INPUTS!$Q$89),AND(INPUTS!$E$89="Yes",D$16=1,D$7>=INPUTS!$R$89,D$7<=INPUTS!$S$89)),"S+C",IF(AND(INPUTS!$E$89="Yes",D$16=1,D$7>=INPUTS!$P$89,D$7<=INPUTS!$Q$89),"S",IF(AND(INPUTS!$E$89="Yes",D$16=1,D$7>=INPUTS!$R$89,D$7<=INPUTS!$S$89),"C",IF(AND(INPUTS!$E$89="Yes",D$17=1,D$7>INPUTS!$S$89),"✓","")))) | E22: =IF(AND(AND(INPUTS!$E$89="Yes",E$16=1,E$7>=INPUTS!$P$89,E$7<=INPUTS!$Q$89),AND(INPUTS!$E$89="Yes",E$16=1,E$7>=INPUTS!$R$89,E$7<=INPUTS!$S$89)),"S+C",IF(AND(INPUTS!$E$89="Yes",E$16=1,E$7>=INPUTS!$P$89,E$7<=INPUTS!$Q$89),"S",IF(AND(INPUTS!$E$89="Yes",E$16=1,E$7>=INPUTS!$R$89,E$7<=INPUTS!$S$89),"C",IF(AND(INPUTS!$E$89="Yes",E$17=1,E$7>INPUTS!$S$89),"✓","")))) | F22: =IF(AND(AND(INPUTS!$E$89="Yes",F$16=1,F$7>=INPUTS!$P$89,F$7<=INPUTS!$Q$89),AND(INPUTS!$E$89="Yes",F$16=1,F$7>=INPUTS!$R$89,F$7<=INPUTS!$S$89)),"S+C",IF(AND(INPUTS!$E$89="Yes",F$16=1,F$7>=INPUTS!$P$89,F$7<=INPUTS!$Q$89),"S",IF(AND(INPUTS!$E$89="Yes",F$16=1,F$7>=INPUTS!$R$89,F$7<=INPUTS!$S$89),"C",IF(AND(INPUTS!$E$89="Yes",F$17=1,F$7>INPUTS!$S$89),"✓","")))) | G22: =IF(AND(AND(INPUTS!$E$89="Yes",G$16=1,G$7>=INPUTS!$P$89,G$7<=INPUTS!$Q$89),AND(INPUTS!$E$89="Yes",G$16=1,G$7>=INPUTS!$R$89,G$7<=INPUTS!$S$89)),"S+C",IF(AND(INPUTS!$E$89="Yes",G$16=1,G$7>=INPUTS!$P$89,G$7<=INPUTS!$Q$89),"S",IF(AND(INPUTS!$E$89="Yes",G$16=1,G$7>=INPUTS!$R$89,G$7<=INPUTS!$S$89),"C",IF(AND(INPUTS!$E$89="Yes",G$17=1,G$7>INPUTS!$S$89),"✓","")))) -> S | H22: =IF(AND(AND(INPUTS!$E$89="Yes",H$16=1,H$7>=INPUTS!$P$89,H$7<=INPUTS!$Q$89),AND(INPUTS!$E$89="Yes",H$16=1,H$7>=INPUTS!$R$89,H$7<=INPUTS!$S$89)),"S+C",IF(AND(INPUTS!$E$89="Yes",H$16=1,H$7>=INPUTS!$P$89,H$7<=INPUTS!$Q$89),"S",IF(AND(INPUTS!$E$89="Yes",H$16=1,H$7>=INPUTS!$R$89,H$7<=INPUTS!$S$89),"C",IF(AND(INPUTS!$E$89="Yes",H$17=1,H$7>INPUTS!$S$89),"✓","")))) -> S+C | I22: =IF(AND(AND(INPUTS!$E$89="Yes",I$16=1,I$7>=INPUTS!$P$89,I$7<=INPUTS!$Q$89),AND(INPUTS!$E$89="Yes",I$16=1,I$7>=INPUTS!$R$89,I$7<=INPUTS!$S$89)),"S+C",IF(AND(INPUTS!$E$89="Yes",I$16=1,I$7>=INPUTS!$P$89,I$7<=INPUTS!$Q$89),"S",IF(AND(INPUTS!$E$89="Yes",I$16=1,I$7>=INPUTS!$R$89,I$7<=INPUTS!$S$89),"C",IF(AND(INPUTS!$E$89="Yes",I$17=1,I$7>INPUTS!$S$89),"✓","")))) -> S+C | J22: =IF(AND(AND(INPUTS!$E$89="Yes",J$16=1,J$7>=INPUTS!$P$89,J$7<=INPUTS!$Q$89),AND(INPUTS!$E$89="Yes",J$16=1,J$7>=INPUTS!$R$89,J$7<=INPUTS!$S$89)),"S+C",IF(AND(INPUTS!$E$89="Yes",J$16=1,J$7>=INPUTS!$P$89,J$7<=INPUTS!$Q$89),"S",IF(AND(INPUTS!$E$89="Yes",J$16=1,J$7>=INPUTS!$R$89,J$7<=INPUTS!$S$89),"C",IF(AND(INPUTS!$E$89="Yes",J$17=1,J$7>INPUTS!$S$89),"✓","")))) -> S+C | K22: =IF(AND(AND(INPUTS!$E$89="Yes",K$16=1,K$7>=INPUTS!$P$89,K$7<=INPUTS!$Q$89),AND(INPUTS!$E$89="Yes",K$16=1,K$7>=INPUTS!$R$89,K$7<=INPUTS!$S$89)),"S+C",IF(AND(INPUTS!$E$89="Yes",K$16=1,K$7>=INPUTS!$P$89,K$7<=INPUTS!$Q$89),"S",IF(AND(INPUTS!$E$89="Yes",K$16=1,K$7>=INPUTS!$R$89,K$7<=INPUTS!$S$89),"C",IF(AND(INPUTS!$E$89="Yes",K$17=1,K$7>INPUTS!$S$89),"✓","")))) -> S+C | ... AQ22: =IF(AND(AND(INPUTS!$E$89="Yes",AQ$16=1,AQ$7>=INPUTS!$P$89,AQ$7<=INPUTS!$Q$89),AND(INPUTS!$E$89="Yes",AQ$16=1,AQ$7>=INPUTS!$R$89,AQ$7<=INPUTS!$S$89)),"S+C",IF(AND(INPUTS!$E$89="Yes",AQ$16=1,AQ$7>=INPUTS!$P$89,AQ$7<=INPUTS!$Q$89),"S",IF(AND(INPUTS!$E$89="Yes",AQ$16=1,AQ$7>=INPUTS!$R$89,AQ$7<=INPUTS!$S$89),"C",IF(AND(INPUTS!$E$89="Yes",AQ$17=1,AQ$7>INPUTS!$S$89),"✓",""))))
B23: =IF(INPUTS!$E$90="Yes",INPUTS!$B$90,"(product row 3 – off)") -> Studios | D23: =IF(AND(AND(INPUTS!$E$90="Yes",D$16=1,D$7>=INPUTS!$P$90,D$7<=INPUTS!$Q$90),AND(INPUTS!$E$90="Yes",D$16=1,D$7>=INPUTS!$R$90,D$7<=INPUTS!$S$90)),"S+C",IF(AND(INPUTS!$E$90="Yes",D$16=1,D$7>=INPUTS!$P$90,D$7<=INPUTS!$Q$90),"S",IF(AND(INPUTS!$E$90="Yes",D$16=1,D$7>=INPUTS!$R$90,D$7<=INPUTS!$S$90),"C",IF(AND(INPUTS!$E$90="Yes",D$17=1,D$7>INPUTS!$S$90),"✓","")))) | E23: =IF(AND(AND(INPUTS!$E$90="Yes",E$16=1,E$7>=INPUTS!$P$90,E$7<=INPUTS!$Q$90),AND(INPUTS!$E$90="Yes",E$16=1,E$7>=INPUTS!$R$90,E$7<=INPUTS!$S$90)),"S+C",IF(AND(INPUTS!$E$90="Yes",E$16=1,E$7>=INPUTS!$P$90,E$7<=INPUTS!$Q$90),"S",IF(AND(INPUTS!$E$90="Yes",E$16=1,E$7>=INPUTS!$R$90,E$7<=INPUTS!$S$90),"C",IF(AND(INPUTS!$E$90="Yes",E$17=1,E$7>INPUTS!$S$90),"✓","")))) | F23: =IF(AND(AND(INPUTS!$E$90="Yes",F$16=1,F$7>=INPUTS!$P$90,F$7<=INPUTS!$Q$90),AND(INPUTS!$E$90="Yes",F$16=1,F$7>=INPUTS!$R$90,F$7<=INPUTS!$S$90)),"S+C",IF(AND(INPUTS!$E$90="Yes",F$16=1,F$7>=INPUTS!$P$90,F$7<=INPUTS!$Q$90),"S",IF(AND(INPUTS!$E$90="Yes",F$16=1,F$7>=INPUTS!$R$90,F$7<=INPUTS!$S$90),"C",IF(AND(INPUTS!$E$90="Yes",F$17=1,F$7>INPUTS!$S$90),"✓","")))) | G23: =IF(AND(AND(INPUTS!$E$90="Yes",G$16=1,G$7>=INPUTS!$P$90,G$7<=INPUTS!$Q$90),AND(INPUTS!$E$90="Yes",G$16=1,G$7>=INPUTS!$R$90,G$7<=INPUTS!$S$90)),"S+C",IF(AND(INPUTS!$E$90="Yes",G$16=1,G$7>=INPUTS!$P$90,G$7<=INPUTS!$Q$90),"S",IF(AND(INPUTS!$E$90="Yes",G$16=1,G$7>=INPUTS!$R$90,G$7<=INPUTS!$S$90),"C",IF(AND(INPUTS!$E$90="Yes",G$17=1,G$7>INPUTS!$S$90),"✓","")))) | H23: =IF(AND(AND(INPUTS!$E$90="Yes",H$16=1,H$7>=INPUTS!$P$90,H$7<=INPUTS!$Q$90),AND(INPUTS!$E$90="Yes",H$16=1,H$7>=INPUTS!$R$90,H$7<=INPUTS!$S$90)),"S+C",IF(AND(INPUTS!$E$90="Yes",H$16=1,H$7>=INPUTS!$P$90,H$7<=INPUTS!$Q$90),"S",IF(AND(INPUTS!$E$90="Yes",H$16=1,H$7>=INPUTS!$R$90,H$7<=INPUTS!$S$90),"C",IF(AND(INPUTS!$E$90="Yes",H$17=1,H$7>INPUTS!$S$90),"✓","")))) | I23: =IF(AND(AND(INPUTS!$E$90="Yes",I$16=1,I$7>=INPUTS!$P$90,I$7<=INPUTS!$Q$90),AND(INPUTS!$E$90="Yes",I$16=1,I$7>=INPUTS!$R$90,I$7<=INPUTS!$S$90)),"S+C",IF(AND(INPUTS!$E$90="Yes",I$16=1,I$7>=INPUTS!$P$90,I$7<=INPUTS!$Q$90),"S",IF(AND(INPUTS!$E$90="Yes",I$16=1,I$7>=INPUTS!$R$90,I$7<=INPUTS!$S$90),"C",IF(AND(INPUTS!$E$90="Yes",I$17=1,I$7>INPUTS!$S$90),"✓","")))) -> S+C | J23: =IF(AND(AND(INPUTS!$E$90="Yes",J$16=1,J$7>=INPUTS!$P$90,J$7<=INPUTS!$Q$90),AND(INPUTS!$E$90="Yes",J$16=1,J$7>=INPUTS!$R$90,J$7<=INPUTS!$S$90)),"S+C",IF(AND(INPUTS!$E$90="Yes",J$16=1,J$7>=INPUTS!$P$90,J$7<=INPUTS!$Q$90),"S",IF(AND(INPUTS!$E$90="Yes",J$16=1,J$7>=INPUTS!$R$90,J$7<=INPUTS!$S$90),"C",IF(AND(INPUTS!$E$90="Yes",J$17=1,J$7>INPUTS!$S$90),"✓","")))) -> S+C | K23: =IF(AND(AND(INPUTS!$E$90="Yes",K$16=1,K$7>=INPUTS!$P$90,K$7<=INPUTS!$Q$90),AND(INPUTS!$E$90="Yes",K$16=1,K$7>=INPUTS!$R$90,K$7<=INPUTS!$S$90)),"S+C",IF(AND(INPUTS!$E$90="Yes",K$16=1,K$7>=INPUTS!$P$90,K$7<=INPUTS!$Q$90),"S",IF(AND(INPUTS!$E$90="Yes",K$16=1,K$7>=INPUTS!$R$90,K$7<=INPUTS!$S$90),"C",IF(AND(INPUTS!$E$90="Yes",K$17=1,K$7>INPUTS!$S$90),"✓","")))) -> S+C | ... AQ23: =IF(AND(AND(INPUTS!$E$90="Yes",AQ$16=1,AQ$7>=INPUTS!$P$90,AQ$7<=INPUTS!$Q$90),AND(INPUTS!$E$90="Yes",AQ$16=1,AQ$7>=INPUTS!$R$90,AQ$7<=INPUTS!$S$90)),"S+C",IF(AND(INPUTS!$E$90="Yes",AQ$16=1,AQ$7>=INPUTS!$P$90,AQ$7<=INPUTS!$Q$90),"S",IF(AND(INPUTS!$E$90="Yes",AQ$16=1,AQ$7>=INPUTS!$R$90,AQ$7<=INPUTS!$S$90),"C",IF(AND(INPUTS!$E$90="Yes",AQ$17=1,AQ$7>INPUTS!$S$90),"✓",""))))
B24: =IF(INPUTS!$E$91="Yes",INPUTS!$B$91,"(product row 4 – off)") -> High-street retail | D24: =IF(AND(AND(INPUTS!$E$91="Yes",D$16=1,D$7>=INPUTS!$P$91,D$7<=INPUTS!$Q$91),AND(INPUTS!$E$91="Yes",D$16=1,D$7>=INPUTS!$R$91,D$7<=INPUTS!$S$91)),"S+C",IF(AND(INPUTS!$E$91="Yes",D$16=1,D$7>=INPUTS!$P$91,D$7<=INPUTS!$Q$91),"S",IF(AND(INPUTS!$E$91="Yes",D$16=1,D$7>=INPUTS!$R$91,D$7<=INPUTS!$S$91),"C",IF(AND(INPUTS!$E$91="Yes",D$17=1,D$7>INPUTS!$S$91),"✓","")))) | E24: =IF(AND(AND(INPUTS!$E$91="Yes",E$16=1,E$7>=INPUTS!$P$91,E$7<=INPUTS!$Q$91),AND(INPUTS!$E$91="Yes",E$16=1,E$7>=INPUTS!$R$91,E$7<=INPUTS!$S$91)),"S+C",IF(AND(INPUTS!$E$91="Yes",E$16=1,E$7>=INPUTS!$P$91,E$7<=INPUTS!$Q$91),"S",IF(AND(INPUTS!$E$91="Yes",E$16=1,E$7>=INPUTS!$R$91,E$7<=INPUTS!$S$91),"C",IF(AND(INPUTS!$E$91="Yes",E$17=1,E$7>INPUTS!$S$91),"✓","")))) | F24: =IF(AND(AND(INPUTS!$E$91="Yes",F$16=1,F$7>=INPUTS!$P$91,F$7<=INPUTS!$Q$91),AND(INPUTS!$E$91="Yes",F$16=1,F$7>=INPUTS!$R$91,F$7<=INPUTS!$S$91)),"S+C",IF(AND(INPUTS!$E$91="Yes",F$16=1,F$7>=INPUTS!$P$91,F$7<=INPUTS!$Q$91),"S",IF(AND(INPUTS!$E$91="Yes",F$16=1,F$7>=INPUTS!$R$91,F$7<=INPUTS!$S$91),"C",IF(AND(INPUTS!$E$91="Yes",F$17=1,F$7>INPUTS!$S$91),"✓","")))) | G24: =IF(AND(AND(INPUTS!$E$91="Yes",G$16=1,G$7>=INPUTS!$P$91,G$7<=INPUTS!$Q$91),AND(INPUTS!$E$91="Yes",G$16=1,G$7>=INPUTS!$R$91,G$7<=INPUTS!$S$91)),"S+C",IF(AND(INPUTS!$E$91="Yes",G$16=1,G$7>=INPUTS!$P$91,G$7<=INPUTS!$Q$91),"S",IF(AND(INPUTS!$E$91="Yes",G$16=1,G$7>=INPUTS!$R$91,G$7<=INPUTS!$S$91),"C",IF(AND(INPUTS!$E$91="Yes",G$17=1,G$7>INPUTS!$S$91),"✓","")))) | H24: =IF(AND(AND(INPUTS!$E$91="Yes",H$16=1,H$7>=INPUTS!$P$91,H$7<=INPUTS!$Q$91),AND(INPUTS!$E$91="Yes",H$16=1,H$7>=INPUTS!$R$91,H$7<=INPUTS!$S$91)),"S+C",IF(AND(INPUTS!$E$91="Yes",H$16=1,H$7>=INPUTS!$P$91,H$7<=INPUTS!$Q$91),"S",IF(AND(INPUTS!$E$91="Yes",H$16=1,H$7>=INPUTS!$R$91,H$7<=INPUTS!$S$91),"C",IF(AND(INPUTS!$E$91="Yes",H$17=1,H$7>INPUTS!$S$91),"✓","")))) | I24: =IF(AND(AND(INPUTS!$E$91="Yes",I$16=1,I$7>=INPUTS!$P$91,I$7<=INPUTS!$Q$91),AND(INPUTS!$E$91="Yes",I$16=1,I$7>=INPUTS!$R$91,I$7<=INPUTS!$S$91)),"S+C",IF(AND(INPUTS!$E$91="Yes",I$16=1,I$7>=INPUTS!$P$91,I$7<=INPUTS!$Q$91),"S",IF(AND(INPUTS!$E$91="Yes",I$16=1,I$7>=INPUTS!$R$91,I$7<=INPUTS!$S$91),"C",IF(AND(INPUTS!$E$91="Yes",I$17=1,I$7>INPUTS!$S$91),"✓","")))) -> C | J24: =IF(AND(AND(INPUTS!$E$91="Yes",J$16=1,J$7>=INPUTS!$P$91,J$7<=INPUTS!$Q$91),AND(INPUTS!$E$91="Yes",J$16=1,J$7>=INPUTS!$R$91,J$7<=INPUTS!$S$91)),"S+C",IF(AND(INPUTS!$E$91="Yes",J$16=1,J$7>=INPUTS!$P$91,J$7<=INPUTS!$Q$91),"S",IF(AND(INPUTS!$E$91="Yes",J$16=1,J$7>=INPUTS!$R$91,J$7<=INPUTS!$S$91),"C",IF(AND(INPUTS!$E$91="Yes",J$17=1,J$7>INPUTS!$S$91),"✓","")))) -> C | K24: =IF(AND(AND(INPUTS!$E$91="Yes",K$16=1,K$7>=INPUTS!$P$91,K$7<=INPUTS!$Q$91),AND(INPUTS!$E$91="Yes",K$16=1,K$7>=INPUTS!$R$91,K$7<=INPUTS!$S$91)),"S+C",IF(AND(INPUTS!$E$91="Yes",K$16=1,K$7>=INPUTS!$P$91,K$7<=INPUTS!$Q$91),"S",IF(AND(INPUTS!$E$91="Yes",K$16=1,K$7>=INPUTS!$R$91,K$7<=INPUTS!$S$91),"C",IF(AND(INPUTS!$E$91="Yes",K$17=1,K$7>INPUTS!$S$91),"✓","")))) -> S+C | ... AQ24: =IF(AND(AND(INPUTS!$E$91="Yes",AQ$16=1,AQ$7>=INPUTS!$P$91,AQ$7<=INPUTS!$Q$91),AND(INPUTS!$E$91="Yes",AQ$16=1,AQ$7>=INPUTS!$R$91,AQ$7<=INPUTS!$S$91)),"S+C",IF(AND(INPUTS!$E$91="Yes",AQ$16=1,AQ$7>=INPUTS!$P$91,AQ$7<=INPUTS!$Q$91),"S",IF(AND(INPUTS!$E$91="Yes",AQ$16=1,AQ$7>=INPUTS!$R$91,AQ$7<=INPUTS!$S$91),"C",IF(AND(INPUTS!$E$91="Yes",AQ$17=1,AQ$7>INPUTS!$S$91),"✓",""))))
B25: =IF(INPUTS!$E$92="Yes",INPUTS!$B$92,"(product row 5 – off)") -> (product row 5 – off) | D25: =IF(AND(AND(INPUTS!$E$92="Yes",D$16=1,D$7>=INPUTS!$P$92,D$7<=INPUTS!$Q$92),AND(INPUTS!$E$92="Yes",D$16=1,D$7>=INPUTS!$R$92,D$7<=INPUTS!$S$92)),"S+C",IF(AND(INPUTS!$E$92="Yes",D$16=1,D$7>=INPUTS!$P$92,D$7<=INPUTS!$Q$92),"S",IF(AND(INPUTS!$E$92="Yes",D$16=1,D$7>=INPUTS!$R$92,D$7<=INPUTS!$S$92),"C",IF(AND(INPUTS!$E$92="Yes",D$17=1,D$7>INPUTS!$S$92),"✓","")))) | E25: =IF(AND(AND(INPUTS!$E$92="Yes",E$16=1,E$7>=INPUTS!$P$92,E$7<=INPUTS!$Q$92),AND(INPUTS!$E$92="Yes",E$16=1,E$7>=INPUTS!$R$92,E$7<=INPUTS!$S$92)),"S+C",IF(AND(INPUTS!$E$92="Yes",E$16=1,E$7>=INPUTS!$P$92,E$7<=INPUTS!$Q$92),"S",IF(AND(INPUTS!$E$92="Yes",E$16=1,E$7>=INPUTS!$R$92,E$7<=INPUTS!$S$92),"C",IF(AND(INPUTS!$E$92="Yes",E$17=1,E$7>INPUTS!$S$92),"✓","")))) | F25: =IF(AND(AND(INPUTS!$E$92="Yes",F$16=1,F$7>=INPUTS!$P$92,F$7<=INPUTS!$Q$92),AND(INPUTS!$E$92="Yes",F$16=1,F$7>=INPUTS!$R$92,F$7<=INPUTS!$S$92)),"S+C",IF(AND(INPUTS!$E$92="Yes",F$16=1,F$7>=INPUTS!$P$92,F$7<=INPUTS!$Q$92),"S",IF(AND(INPUTS!$E$92="Yes",F$16=1,F$7>=INPUTS!$R$92,F$7<=INPUTS!$S$92),"C",IF(AND(INPUTS!$E$92="Yes",F$17=1,F$7>INPUTS!$S$92),"✓","")))) | G25: =IF(AND(AND(INPUTS!$E$92="Yes",G$16=1,G$7>=INPUTS!$P$92,G$7<=INPUTS!$Q$92),AND(INPUTS!$E$92="Yes",G$16=1,G$7>=INPUTS!$R$92,G$7<=INPUTS!$S$92)),"S+C",IF(AND(INPUTS!$E$92="Yes",G$16=1,G$7>=INPUTS!$P$92,G$7<=INPUTS!$Q$92),"S",IF(AND(INPUTS!$E$92="Yes",G$16=1,G$7>=INPUTS!$R$92,G$7<=INPUTS!$S$92),"C",IF(AND(INPUTS!$E$92="Yes",G$17=1,G$7>INPUTS!$S$92),"✓","")))) | H25: =IF(AND(AND(INPUTS!$E$92="Yes",H$16=1,H$7>=INPUTS!$P$92,H$7<=INPUTS!$Q$92),AND(INPUTS!$E$92="Yes",H$16=1,H$7>=INPUTS!$R$92,H$7<=INPUTS!$S$92)),"S+C",IF(AND(INPUTS!$E$92="Yes",H$16=1,H$7>=INPUTS!$P$92,H$7<=INPUTS!$Q$92),"S",IF(AND(INPUTS!$E$92="Yes",H$16=1,H$7>=INPUTS!$R$92,H$7<=INPUTS!$S$92),"C",IF(AND(INPUTS!$E$92="Yes",H$17=1,H$7>INPUTS!$S$92),"✓","")))) | I25: =IF(AND(AND(INPUTS!$E$92="Yes",I$16=1,I$7>=INPUTS!$P$92,I$7<=INPUTS!$Q$92),AND(INPUTS!$E$92="Yes",I$16=1,I$7>=INPUTS!$R$92,I$7<=INPUTS!$S$92)),"S+C",IF(AND(INPUTS!$E$92="Yes",I$16=1,I$7>=INPUTS!$P$92,I$7<=INPUTS!$Q$92),"S",IF(AND(INPUTS!$E$92="Yes",I$16=1,I$7>=INPUTS!$R$92,I$7<=INPUTS!$S$92),"C",IF(AND(INPUTS!$E$92="Yes",I$17=1,I$7>INPUTS!$S$92),"✓","")))) | J25: =IF(AND(AND(INPUTS!$E$92="Yes",J$16=1,J$7>=INPUTS!$P$92,J$7<=INPUTS!$Q$92),AND(INPUTS!$E$92="Yes",J$16=1,J$7>=INPUTS!$R$92,J$7<=INPUTS!$S$92)),"S+C",IF(AND(INPUTS!$E$92="Yes",J$16=1,J$7>=INPUTS!$P$92,J$7<=INPUTS!$Q$92),"S",IF(AND(INPUTS!$E$92="Yes",J$16=1,J$7>=INPUTS!$R$92,J$7<=INPUTS!$S$92),"C",IF(AND(INPUTS!$E$92="Yes",J$17=1,J$7>INPUTS!$S$92),"✓","")))) | K25: =IF(AND(AND(INPUTS!$E$92="Yes",K$16=1,K$7>=INPUTS!$P$92,K$7<=INPUTS!$Q$92),AND(INPUTS!$E$92="Yes",K$16=1,K$7>=INPUTS!$R$92,K$7<=INPUTS!$S$92)),"S+C",IF(AND(INPUTS!$E$92="Yes",K$16=1,K$7>=INPUTS!$P$92,K$7<=INPUTS!$Q$92),"S",IF(AND(INPUTS!$E$92="Yes",K$16=1,K$7>=INPUTS!$R$92,K$7<=INPUTS!$S$92),"C",IF(AND(INPUTS!$E$92="Yes",K$17=1,K$7>INPUTS!$S$92),"✓","")))) | ... AQ25: =IF(AND(AND(INPUTS!$E$92="Yes",AQ$16=1,AQ$7>=INPUTS!$P$92,AQ$7<=INPUTS!$Q$92),AND(INPUTS!$E$92="Yes",AQ$16=1,AQ$7>=INPUTS!$R$92,AQ$7<=INPUTS!$S$92)),"S+C",IF(AND(INPUTS!$E$92="Yes",AQ$16=1,AQ$7>=INPUTS!$P$92,AQ$7<=INPUTS!$Q$92),"S",IF(AND(INPUTS!$E$92="Yes",AQ$16=1,AQ$7>=INPUTS!$R$92,AQ$7<=INPUTS!$S$92),"C",IF(AND(INPUTS!$E$92="Yes",AQ$17=1,AQ$7>INPUTS!$S$92),"✓",""))))
B26: =IF(INPUTS!$E$93="Yes",INPUTS!$B$93,"(product row 6 – off)") -> (product row 6 – off) | D26: =IF(AND(AND(INPUTS!$E$93="Yes",D$16=1,D$7>=INPUTS!$P$93,D$7<=INPUTS!$Q$93),AND(INPUTS!$E$93="Yes",D$16=1,D$7>=INPUTS!$R$93,D$7<=INPUTS!$S$93)),"S+C",IF(AND(INPUTS!$E$93="Yes",D$16=1,D$7>=INPUTS!$P$93,D$7<=INPUTS!$Q$93),"S",IF(AND(INPUTS!$E$93="Yes",D$16=1,D$7>=INPUTS!$R$93,D$7<=INPUTS!$S$93),"C",IF(AND(INPUTS!$E$93="Yes",D$17=1,D$7>INPUTS!$S$93),"✓","")))) | E26: =IF(AND(AND(INPUTS!$E$93="Yes",E$16=1,E$7>=INPUTS!$P$93,E$7<=INPUTS!$Q$93),AND(INPUTS!$E$93="Yes",E$16=1,E$7>=INPUTS!$R$93,E$7<=INPUTS!$S$93)),"S+C",IF(AND(INPUTS!$E$93="Yes",E$16=1,E$7>=INPUTS!$P$93,E$7<=INPUTS!$Q$93),"S",IF(AND(INPUTS!$E$93="Yes",E$16=1,E$7>=INPUTS!$R$93,E$7<=INPUTS!$S$93),"C",IF(AND(INPUTS!$E$93="Yes",E$17=1,E$7>INPUTS!$S$93),"✓","")))) | F26: =IF(AND(AND(INPUTS!$E$93="Yes",F$16=1,F$7>=INPUTS!$P$93,F$7<=INPUTS!$Q$93),AND(INPUTS!$E$93="Yes",F$16=1,F$7>=INPUTS!$R$93,F$7<=INPUTS!$S$93)),"S+C",IF(AND(INPUTS!$E$93="Yes",F$16=1,F$7>=INPUTS!$P$93,F$7<=INPUTS!$Q$93),"S",IF(AND(INPUTS!$E$93="Yes",F$16=1,F$7>=INPUTS!$R$93,F$7<=INPUTS!$S$93),"C",IF(AND(INPUTS!$E$93="Yes",F$17=1,F$7>INPUTS!$S$93),"✓","")))) | G26: =IF(AND(AND(INPUTS!$E$93="Yes",G$16=1,G$7>=INPUTS!$P$93,G$7<=INPUTS!$Q$93),AND(INPUTS!$E$93="Yes",G$16=1,G$7>=INPUTS!$R$93,G$7<=INPUTS!$S$93)),"S+C",IF(AND(INPUTS!$E$93="Yes",G$16=1,G$7>=INPUTS!$P$93,G$7<=INPUTS!$Q$93),"S",IF(AND(INPUTS!$E$93="Yes",G$16=1,G$7>=INPUTS!$R$93,G$7<=INPUTS!$S$93),"C",IF(AND(INPUTS!$E$93="Yes",G$17=1,G$7>INPUTS!$S$93),"✓","")))) | H26: =IF(AND(AND(INPUTS!$E$93="Yes",H$16=1,H$7>=INPUTS!$P$93,H$7<=INPUTS!$Q$93),AND(INPUTS!$E$93="Yes",H$16=1,H$7>=INPUTS!$R$93,H$7<=INPUTS!$S$93)),"S+C",IF(AND(INPUTS!$E$93="Yes",H$16=1,H$7>=INPUTS!$P$93,H$7<=INPUTS!$Q$93),"S",IF(AND(INPUTS!$E$93="Yes",H$16=1,H$7>=INPUTS!$R$93,H$7<=INPUTS!$S$93),"C",IF(AND(INPUTS!$E$93="Yes",H$17=1,H$7>INPUTS!$S$93),"✓","")))) | I26: =IF(AND(AND(INPUTS!$E$93="Yes",I$16=1,I$7>=INPUTS!$P$93,I$7<=INPUTS!$Q$93),AND(INPUTS!$E$93="Yes",I$16=1,I$7>=INPUTS!$R$93,I$7<=INPUTS!$S$93)),"S+C",IF(AND(INPUTS!$E$93="Yes",I$16=1,I$7>=INPUTS!$P$93,I$7<=INPUTS!$Q$93),"S",IF(AND(INPUTS!$E$93="Yes",I$16=1,I$7>=INPUTS!$R$93,I$7<=INPUTS!$S$93),"C",IF(AND(INPUTS!$E$93="Yes",I$17=1,I$7>INPUTS!$S$93),"✓","")))) | J26: =IF(AND(AND(INPUTS!$E$93="Yes",J$16=1,J$7>=INPUTS!$P$93,J$7<=INPUTS!$Q$93),AND(INPUTS!$E$93="Yes",J$16=1,J$7>=INPUTS!$R$93,J$7<=INPUTS!$S$93)),"S+C",IF(AND(INPUTS!$E$93="Yes",J$16=1,J$7>=INPUTS!$P$93,J$7<=INPUTS!$Q$93),"S",IF(AND(INPUTS!$E$93="Yes",J$16=1,J$7>=INPUTS!$R$93,J$7<=INPUTS!$S$93),"C",IF(AND(INPUTS!$E$93="Yes",J$17=1,J$7>INPUTS!$S$93),"✓","")))) | K26: =IF(AND(AND(INPUTS!$E$93="Yes",K$16=1,K$7>=INPUTS!$P$93,K$7<=INPUTS!$Q$93),AND(INPUTS!$E$93="Yes",K$16=1,K$7>=INPUTS!$R$93,K$7<=INPUTS!$S$93)),"S+C",IF(AND(INPUTS!$E$93="Yes",K$16=1,K$7>=INPUTS!$P$93,K$7<=INPUTS!$Q$93),"S",IF(AND(INPUTS!$E$93="Yes",K$16=1,K$7>=INPUTS!$R$93,K$7<=INPUTS!$S$93),"C",IF(AND(INPUTS!$E$93="Yes",K$17=1,K$7>INPUTS!$S$93),"✓","")))) | ... AQ26: =IF(AND(AND(INPUTS!$E$93="Yes",AQ$16=1,AQ$7>=INPUTS!$P$93,AQ$7<=INPUTS!$Q$93),AND(INPUTS!$E$93="Yes",AQ$16=1,AQ$7>=INPUTS!$R$93,AQ$7<=INPUTS!$S$93)),"S+C",IF(AND(INPUTS!$E$93="Yes",AQ$16=1,AQ$7>=INPUTS!$P$93,AQ$7<=INPUTS!$Q$93),"S",IF(AND(INPUTS!$E$93="Yes",AQ$16=1,AQ$7>=INPUTS!$R$93,AQ$7<=INPUTS!$S$93),"C",IF(AND(INPUTS!$E$93="Yes",AQ$17=1,AQ$7>INPUTS!$S$93),"✓",""))))
B27: =IF(INPUTS!$E$94="Yes",INPUTS!$B$94,"(product row 7 – off)") -> (product row 7 – off) | D27: =IF(AND(AND(INPUTS!$E$94="Yes",D$16=1,D$7>=INPUTS!$P$94,D$7<=INPUTS!$Q$94),AND(INPUTS!$E$94="Yes",D$16=1,D$7>=INPUTS!$R$94,D$7<=INPUTS!$S$94)),"S+C",IF(AND(INPUTS!$E$94="Yes",D$16=1,D$7>=INPUTS!$P$94,D$7<=INPUTS!$Q$94),"S",IF(AND(INPUTS!$E$94="Yes",D$16=1,D$7>=INPUTS!$R$94,D$7<=INPUTS!$S$94),"C",IF(AND(INPUTS!$E$94="Yes",D$17=1,D$7>INPUTS!$S$94),"✓","")))) | E27: =IF(AND(AND(INPUTS!$E$94="Yes",E$16=1,E$7>=INPUTS!$P$94,E$7<=INPUTS!$Q$94),AND(INPUTS!$E$94="Yes",E$16=1,E$7>=INPUTS!$R$94,E$7<=INPUTS!$S$94)),"S+C",IF(AND(INPUTS!$E$94="Yes",E$16=1,E$7>=INPUTS!$P$94,E$7<=INPUTS!$Q$94),"S",IF(AND(INPUTS!$E$94="Yes",E$16=1,E$7>=INPUTS!$R$94,E$7<=INPUTS!$S$94),"C",IF(AND(INPUTS!$E$94="Yes",E$17=1,E$7>INPUTS!$S$94),"✓","")))) | F27: =IF(AND(AND(INPUTS!$E$94="Yes",F$16=1,F$7>=INPUTS!$P$94,F$7<=INPUTS!$Q$94),AND(INPUTS!$E$94="Yes",F$16=1,F$7>=INPUTS!$R$94,F$7<=INPUTS!$S$94)),"S+C",IF(AND(INPUTS!$E$94="Yes",F$16=1,F$7>=INPUTS!$P$94,F$7<=INPUTS!$Q$94),"S",IF(AND(INPUTS!$E$94="Yes",F$16=1,F$7>=INPUTS!$R$94,F$7<=INPUTS!$S$94),"C",IF(AND(INPUTS!$E$94="Yes",F$17=1,F$7>INPUTS!$S$94),"✓","")))) | G27: =IF(AND(AND(INPUTS!$E$94="Yes",G$16=1,G$7>=INPUTS!$P$94,G$7<=INPUTS!$Q$94),AND(INPUTS!$E$94="Yes",G$16=1,G$7>=INPUTS!$R$94,G$7<=INPUTS!$S$94)),"S+C",IF(AND(INPUTS!$E$94="Yes",G$16=1,G$7>=INPUTS!$P$94,G$7<=INPUTS!$Q$94),"S",IF(AND(INPUTS!$E$94="Yes",G$16=1,G$7>=INPUTS!$R$94,G$7<=INPUTS!$S$94),"C",IF(AND(INPUTS!$E$94="Yes",G$17=1,G$7>INPUTS!$S$94),"✓","")))) | H27: =IF(AND(AND(INPUTS!$E$94="Yes",H$16=1,H$7>=INPUTS!$P$94,H$7<=INPUTS!$Q$94),AND(INPUTS!$E$94="Yes",H$16=1,H$7>=INPUTS!$R$94,H$7<=INPUTS!$S$94)),"S+C",IF(AND(INPUTS!$E$94="Yes",H$16=1,H$7>=INPUTS!$P$94,H$7<=INPUTS!$Q$94),"S",IF(AND(INPUTS!$E$94="Yes",H$16=1,H$7>=INPUTS!$R$94,H$7<=INPUTS!$S$94),"C",IF(AND(INPUTS!$E$94="Yes",H$17=1,H$7>INPUTS!$S$94),"✓","")))) | I27: =IF(AND(AND(INPUTS!$E$94="Yes",I$16=1,I$7>=INPUTS!$P$94,I$7<=INPUTS!$Q$94),AND(INPUTS!$E$94="Yes",I$16=1,I$7>=INPUTS!$R$94,I$7<=INPUTS!$S$94)),"S+C",IF(AND(INPUTS!$E$94="Yes",I$16=1,I$7>=INPUTS!$P$94,I$7<=INPUTS!$Q$94),"S",IF(AND(INPUTS!$E$94="Yes",I$16=1,I$7>=INPUTS!$R$94,I$7<=INPUTS!$S$94),"C",IF(AND(INPUTS!$E$94="Yes",I$17=1,I$7>INPUTS!$S$94),"✓","")))) | J27: =IF(AND(AND(INPUTS!$E$94="Yes",J$16=1,J$7>=INPUTS!$P$94,J$7<=INPUTS!$Q$94),AND(INPUTS!$E$94="Yes",J$16=1,J$7>=INPUTS!$R$94,J$7<=INPUTS!$S$94)),"S+C",IF(AND(INPUTS!$E$94="Yes",J$16=1,J$7>=INPUTS!$P$94,J$7<=INPUTS!$Q$94),"S",IF(AND(INPUTS!$E$94="Yes",J$16=1,J$7>=INPUTS!$R$94,J$7<=INPUTS!$S$94),"C",IF(AND(INPUTS!$E$94="Yes",J$17=1,J$7>INPUTS!$S$94),"✓","")))) | K27: =IF(AND(AND(INPUTS!$E$94="Yes",K$16=1,K$7>=INPUTS!$P$94,K$7<=INPUTS!$Q$94),AND(INPUTS!$E$94="Yes",K$16=1,K$7>=INPUTS!$R$94,K$7<=INPUTS!$S$94)),"S+C",IF(AND(INPUTS!$E$94="Yes",K$16=1,K$7>=INPUTS!$P$94,K$7<=INPUTS!$Q$94),"S",IF(AND(INPUTS!$E$94="Yes",K$16=1,K$7>=INPUTS!$R$94,K$7<=INPUTS!$S$94),"C",IF(AND(INPUTS!$E$94="Yes",K$17=1,K$7>INPUTS!$S$94),"✓","")))) | ... AQ27: =IF(AND(AND(INPUTS!$E$94="Yes",AQ$16=1,AQ$7>=INPUTS!$P$94,AQ$7<=INPUTS!$Q$94),AND(INPUTS!$E$94="Yes",AQ$16=1,AQ$7>=INPUTS!$R$94,AQ$7<=INPUTS!$S$94)),"S+C",IF(AND(INPUTS!$E$94="Yes",AQ$16=1,AQ$7>=INPUTS!$P$94,AQ$7<=INPUTS!$Q$94),"S",IF(AND(INPUTS!$E$94="Yes",AQ$16=1,AQ$7>=INPUTS!$R$94,AQ$7<=INPUTS!$S$94),"C",IF(AND(INPUTS!$E$94="Yes",AQ$17=1,AQ$7>INPUTS!$S$94),"✓",""))))
B28: =IF(INPUTS!$E$95="Yes",INPUTS!$B$95,"(product row 8 – off)") -> (product row 8 – off) | D28: =IF(AND(AND(INPUTS!$E$95="Yes",D$16=1,D$7>=INPUTS!$P$95,D$7<=INPUTS!$Q$95),AND(INPUTS!$E$95="Yes",D$16=1,D$7>=INPUTS!$R$95,D$7<=INPUTS!$S$95)),"S+C",IF(AND(INPUTS!$E$95="Yes",D$16=1,D$7>=INPUTS!$P$95,D$7<=INPUTS!$Q$95),"S",IF(AND(INPUTS!$E$95="Yes",D$16=1,D$7>=INPUTS!$R$95,D$7<=INPUTS!$S$95),"C",IF(AND(INPUTS!$E$95="Yes",D$17=1,D$7>INPUTS!$S$95),"✓","")))) | E28: =IF(AND(AND(INPUTS!$E$95="Yes",E$16=1,E$7>=INPUTS!$P$95,E$7<=INPUTS!$Q$95),AND(INPUTS!$E$95="Yes",E$16=1,E$7>=INPUTS!$R$95,E$7<=INPUTS!$S$95)),"S+C",IF(AND(INPUTS!$E$95="Yes",E$16=1,E$7>=INPUTS!$P$95,E$7<=INPUTS!$Q$95),"S",IF(AND(INPUTS!$E$95="Yes",E$16=1,E$7>=INPUTS!$R$95,E$7<=INPUTS!$S$95),"C",IF(AND(INPUTS!$E$95="Yes",E$17=1,E$7>INPUTS!$S$95),"✓","")))) | F28: =IF(AND(AND(INPUTS!$E$95="Yes",F$16=1,F$7>=INPUTS!$P$95,F$7<=INPUTS!$Q$95),AND(INPUTS!$E$95="Yes",F$16=1,F$7>=INPUTS!$R$95,F$7<=INPUTS!$S$95)),"S+C",IF(AND(INPUTS!$E$95="Yes",F$16=1,F$7>=INPUTS!$P$95,F$7<=INPUTS!$Q$95),"S",IF(AND(INPUTS!$E$95="Yes",F$16=1,F$7>=INPUTS!$R$95,F$7<=INPUTS!$S$95),"C",IF(AND(INPUTS!$E$95="Yes",F$17=1,F$7>INPUTS!$S$95),"✓","")))) | G28: =IF(AND(AND(INPUTS!$E$95="Yes",G$16=1,G$7>=INPUTS!$P$95,G$7<=INPUTS!$Q$95),AND(INPUTS!$E$95="Yes",G$16=1,G$7>=INPUTS!$R$95,G$7<=INPUTS!$S$95)),"S+C",IF(AND(INPUTS!$E$95="Yes",G$16=1,G$7>=INPUTS!$P$95,G$7<=INPUTS!$Q$95),"S",IF(AND(INPUTS!$E$95="Yes",G$16=1,G$7>=INPUTS!$R$95,G$7<=INPUTS!$S$95),"C",IF(AND(INPUTS!$E$95="Yes",G$17=1,G$7>INPUTS!$S$95),"✓","")))) | H28: =IF(AND(AND(INPUTS!$E$95="Yes",H$16=1,H$7>=INPUTS!$P$95,H$7<=INPUTS!$Q$95),AND(INPUTS!$E$95="Yes",H$16=1,H$7>=INPUTS!$R$95,H$7<=INPUTS!$S$95)),"S+C",IF(AND(INPUTS!$E$95="Yes",H$16=1,H$7>=INPUTS!$P$95,H$7<=INPUTS!$Q$95),"S",IF(AND(INPUTS!$E$95="Yes",H$16=1,H$7>=INPUTS!$R$95,H$7<=INPUTS!$S$95),"C",IF(AND(INPUTS!$E$95="Yes",H$17=1,H$7>INPUTS!$S$95),"✓","")))) | I28: =IF(AND(AND(INPUTS!$E$95="Yes",I$16=1,I$7>=INPUTS!$P$95,I$7<=INPUTS!$Q$95),AND(INPUTS!$E$95="Yes",I$16=1,I$7>=INPUTS!$R$95,I$7<=INPUTS!$S$95)),"S+C",IF(AND(INPUTS!$E$95="Yes",I$16=1,I$7>=INPUTS!$P$95,I$7<=INPUTS!$Q$95),"S",IF(AND(INPUTS!$E$95="Yes",I$16=1,I$7>=INPUTS!$R$95,I$7<=INPUTS!$S$95),"C",IF(AND(INPUTS!$E$95="Yes",I$17=1,I$7>INPUTS!$S$95),"✓","")))) | J28: =IF(AND(AND(INPUTS!$E$95="Yes",J$16=1,J$7>=INPUTS!$P$95,J$7<=INPUTS!$Q$95),AND(INPUTS!$E$95="Yes",J$16=1,J$7>=INPUTS!$R$95,J$7<=INPUTS!$S$95)),"S+C",IF(AND(INPUTS!$E$95="Yes",J$16=1,J$7>=INPUTS!$P$95,J$7<=INPUTS!$Q$95),"S",IF(AND(INPUTS!$E$95="Yes",J$16=1,J$7>=INPUTS!$R$95,J$7<=INPUTS!$S$95),"C",IF(AND(INPUTS!$E$95="Yes",J$17=1,J$7>INPUTS!$S$95),"✓","")))) | K28: =IF(AND(AND(INPUTS!$E$95="Yes",K$16=1,K$7>=INPUTS!$P$95,K$7<=INPUTS!$Q$95),AND(INPUTS!$E$95="Yes",K$16=1,K$7>=INPUTS!$R$95,K$7<=INPUTS!$S$95)),"S+C",IF(AND(INPUTS!$E$95="Yes",K$16=1,K$7>=INPUTS!$P$95,K$7<=INPUTS!$Q$95),"S",IF(AND(INPUTS!$E$95="Yes",K$16=1,K$7>=INPUTS!$R$95,K$7<=INPUTS!$S$95),"C",IF(AND(INPUTS!$E$95="Yes",K$17=1,K$7>INPUTS!$S$95),"✓","")))) | ... AQ28: =IF(AND(AND(INPUTS!$E$95="Yes",AQ$16=1,AQ$7>=INPUTS!$P$95,AQ$7<=INPUTS!$Q$95),AND(INPUTS!$E$95="Yes",AQ$16=1,AQ$7>=INPUTS!$R$95,AQ$7<=INPUTS!$S$95)),"S+C",IF(AND(INPUTS!$E$95="Yes",AQ$16=1,AQ$7>=INPUTS!$P$95,AQ$7<=INPUTS!$Q$95),"S",IF(AND(INPUTS!$E$95="Yes",AQ$16=1,AQ$7>=INPUTS!$R$95,AQ$7<=INPUTS!$S$95),"C",IF(AND(INPUTS!$E$95="Yes",AQ$17=1,AQ$7>INPUTS!$S$95),"✓",""))))
